Workbook

Sheet Dashboard
A1: 📚 STUDENT PLANNER — DASHBOARD
A3: MENU | C3: Hôm nay | E3: Ngày | G3: Bắt đầu | I3: Kết thúc | K3: Tuần học hiện tại
A4: =HYPERLINK("#gid=2127813405","Hướng dẫn") -> Hướng dẫn | C4: =CHOOSE(WEEKDAY(TODAY(),2),"Thứ Hai","Thứ Ba","Thứ Tư","Thứ Năm","Thứ Sáu","Thứ Bảy","Chủ Nhật") -> Chủ Nhật | E4: =TODAY() -> 46306 | G4: ='Thông tin lớp học'!B3 -> 46258 | I4: ='Thông tin lớp học'!B4 -> 46362 | K4: =IF(TODAY()<G4,"Chưa bắt đầu",IF(TODAY()>I4,"Đã kết thúc","Tuần "&MIN('Thông tin lớp học'!B5,INT((TODAY()-G4)/7)+1)&" / "&'Thông tin lớp học'!B5)) -> Tuần 7 / 15
A5: =HYPERLINK("#gid=178478100","Thông tin lớp học") -> Thông tin lớp học | C5: ="🎯 GPA DỰ KIẾN: " & ROUND('Thông tin lớp học'!$D$26, 2) & " / 4.0 | Hệ 10: " & ROUND('Thông tin lớp học'!$C$26, 2) & " • " & 'Thông tin lớp học'!$E$26 -> 🎯 GPA DỰ KIẾN: 3,6 / 4.0 | Hệ 10: 8,17 • Xuất sắc | K5: =IFERROR(__xludf.DUMMYFUNCTION("SPARKLINE(MIN(1, MAX(0, (TODAY()-'Thông tin lớp học'!$B$3)/('Thông tin lớp học'!$B$4-'Thông tin lớp học'!$B$3))), {""charttype"",""bar""; ""max"",1; ""color1"",""#1a73e8""})"),"")
A6: =HYPERLINK("#gid=1916662489","Lịch học") -> Lịch học | C6: Bài tập cần làm | E6: Bài tập quá hạn | G6: Việc cần làm còn lại | I6: Tỷ lệ chuyên cần | K6: Thói quen hôm nay | M6: Tiến độ giáo trình
A7: =HYPERLINK("#gid=906972626","Lịch tuần") -> Lịch tuần | C7: ='Bảng theo dõi bài tập'!D4 -> 6 | E7: ='Bảng theo dõi bài tập'!F4 -> 3 | G7: ='Danh sách việc cần làm'!D4 -> 5 | I7: ='Bảng theo dõi chuyên cần'!E13 -> 0.92105263 | K7: {=IF(AND('Habit Tracker'!B3=YEAR(TODAY()),'Habit Tracker'!B4=MONTH(TODAY())),(COUNTIF(INDEX('Habit Tracker'!$B$26:$AF$40,0,DAY(TODAY())),TRUE)+COUNTIF(INDEX('Habit Tracker'!$B$26:$AF$40,0,DAY(TODAY())),"✔"))&" / "&COUNTA('Habit Tracker'!$A$26:$A$40),"–")} -> 0 / 12 | M7: ='Quản lý giáo trình'!C3 -> 0.58333333
A8: =HYPERLINK("#gid=1884952073","Hoạt động") -> Hoạt động | C8: =IFERROR(__xludf.DUMMYFUNCTION("SPARKLINE(IF('Bảng theo dõi bài tập'!$B$4=0, 0, 'Bảng theo dõi bài tập'!$C$4/'Bảng theo dõi bài tập'!$B$4), {""charttype"",""bar""; ""max"",1; ""color1"",""#1a73e8""})"),"") | E8: =IF('Bảng theo dõi bài tập'!$G$4>0, "Hạn gấp: " & 'Bảng theo dõi bài tập'!$G$4 & " bài", "✓ Đúng hạn") -> Hạn gấp: 1 bài | G8: =IFERROR(__xludf.DUMMYFUNCTION("SPARKLINE(IF('Danh sách việc cần làm'!$B$4=0, 0, 'Danh sách việc cần làm'!$C$4/'Danh sách việc cần làm'!$B$4), {""charttype"",""bar""; ""max"",1; ""color1"",""#1a73e8""})"),"") | I8: =IFERROR(__xludf.DUMMYFUNCTION("SPARKLINE('Bảng theo dõi chuyên cần'!$E$13, {""charttype"",""bar""; ""max"",1; ""color1"",""#059669""})"),"") | K8: =IFERROR(__xludf.DUMMYFUNCTION("SPARKLINE(IF(COUNTA('Habit Tracker'!$A$26:$A$40)=0, 0, (COUNTIF(INDEX('Habit Tracker'!$B$26:$AF$40, 0, DAY(TODAY())), TRUE) + COUNTIF(INDEX('Habit Tracker'!$B$26:$AF$40, 0, DAY(TODAY())), ""✔"")) / COUNTA('Habit Tracker'!$A$26:$A$40)), {""charttype"",""ba"&"r""; ""max"",1; ""color1"",""#6246f0""})"),"") | M8: =IFERROR(__xludf.DUMMYFUNCTION("SPARKLINE(IF('Quản lý giáo trình'!$A$3=0, 0, 'Quản lý giáo trình'!$B$3/'Quản lý giáo trình'!$A$3), {""charttype"",""bar""; ""max"",1; ""color1"",""#059669""})"),"")
A9: =HYPERLINK("#gid=849745244","Bảng theo dõi bài tập") -> Bảng theo dõi bài tập | C9: Lớp học hôm nay | G9: Hạn nộp sắp tới
A10: =HYPERLINK("#gid=1203904754","Lịch bài tập") -> Lịch bài tập | C10: {=IFERROR(INDEX('Thông tin lớp học'!$G$10:$G$49,MATCH(1,'Thông tin lớp học'!$L$10:$L$49,0)),"Hôm nay không có lớp 🎉")} -> Hôm nay không có lớp 🎉 | E10: {=IFERROR(TEXT(INDEX('Thông tin lớp học'!$I$10:$I$49,MATCH(1,'Thông tin lớp học'!$L$10:$L$49,0)),"hh:mm")&"–"&TEXT(INDEX('Thông tin lớp học'!$J$10:$J$49,MATCH(1,'Thông tin lớp học'!$L$10:$L$49,0)),"hh:mm")&" "&INDEX('Thông tin lớp học'!$K$10:$K$49,MATCH(1,'Thông tin lớp học'!$L$10:$L$49,0)),"")} | G10: {=IFERROR(INDEX('Bảng theo dõi bài tập'!$A$23:$A$72,MATCH(1,'Bảng theo dõi bài tập'!$K$23:$K$72,0))&": "&INDEX('Bảng theo dõi bài tập'!$B$23:$B$72,MATCH(1,'Bảng theo dõi bài tập'!$K$23:$K$72,0)),"Không có hạn nộp 🎉")} -> Kỹ năng mềm: Thực hành thuyết trình nhóm | K10: {=IFERROR(INDEX('Bảng theo dõi bài tập'!$G$23:$G$72,MATCH(1,'Bảng theo dõi bài tập'!$K$23:$K$72,0)),"")} -> 46300 | M10: =IFERROR(IF(K10-TODAY()<0,"Quá hạn "&(TODAY()-K10)&" ngày",IF(K10=TODAY(),"Hôm nay","Còn "&(K10-TODAY())&" ngày")),"") -> Quá hạn 6 ngày
A11: =HYPERLINK("#gid=1921034169","Danh sách việc cần làm") -> Danh sách việc cần làm | C11: {=IFERROR(INDEX('Thông tin lớp học'!$G$10:$G$49,MATCH(2,'Thông tin lớp học'!$L$10:$L$49,0)),"")} | E11: {=IFERROR(TEXT(INDEX('Thông tin lớp học'!$I$10:$I$49,MATCH(2,'Thông tin lớp học'!$L$10:$L$49,0)),"hh:mm")&"–"&TEXT(INDEX('Thông tin lớp học'!$J$10:$J$49,MATCH(2,'Thông tin lớp học'!$L$10:$L$49,0)),"hh:mm")&" "&INDEX('Thông tin lớp học'!$K$10:$K$49,MATCH(2,'Thông tin lớp học'!$L$10:$L$49,0)),"")} | G11: {=IFERROR(INDEX('Bảng theo dõi bài tập'!$A$23:$A$72,MATCH(2,'Bảng theo dõi bài tập'!$K$23:$K$72,0))&": "&INDEX('Bảng theo dõi bài tập'!$B$23:$B$72,MATCH(2,'Bảng theo dõi bài tập'!$K$23:$K$72,0)),"")} -> Toán cao cấp: Kiểm tra giữa kỳ tích phân | K11: {=IFERROR(INDEX('Bảng theo dõi bài tập'!$G$23:$G$72,MATCH(2,'Bảng theo dõi bài tập'!$K$23:$K$72,0)),"")} -> 46302 | M11: =IFERROR(IF(K11-TODAY()<0,"Quá hạn "&(TODAY()-K11)&" ngày",IF(K11=TODAY(),"Hôm nay","Còn "&(K11-TODAY())&" ngày")),"") -> Quá hạn 4 ngày
A12: =HYPERLINK("#gid=992210349", "Nhật ký nhiệm vụ") -> Nhật ký nhiệm vụ | C12: {=IFERROR(INDEX('Thông tin lớp học'!$G$10:$G$49,MATCH(3,'Thông tin lớp học'!$L$10:$L$49,0)),"")} | E12: {=IFERROR(TEXT(INDEX('Thông tin lớp học'!$I$10:$I$49,MATCH(3,'Thông tin lớp học'!$L$10:$L$49,0)),"hh:mm")&"–"&TEXT(INDEX('Thông tin lớp học'!$J$10:$J$49,MATCH(3,'Thông tin lớp học'!$L$10:$L$49,0)),"hh:mm")&" "&INDEX('Thông tin lớp học'!$K$10:$K$49,MATCH(3,'Thông tin lớp học'!$L$10:$L$49,0)),"")} | G12: {=IFERROR(INDEX('Bảng theo dõi bài tập'!$A$23:$A$72,MATCH(3,'Bảng theo dõi bài tập'!$K$23:$K$72,0))&": "&INDEX('Bảng theo dõi bài tập'!$B$23:$B$72,MATCH(3,'Bảng theo dõi bài tập'!$K$23:$K$72,0)),"")} -> Tiếng Anh giao tiếp: Bài tập viết thư thương mại | K12: {=IFERROR(INDEX('Bảng theo dõi bài tập'!$G$23:$G$72,MATCH(3,'Bảng theo dõi bài tập'!$K$23:$K$72,0)),"")} -> 46304 | M12: =IFERROR(IF(K12-TODAY()<0,"Quá hạn "&(TODAY()-K12)&" ngày",IF(K12=TODAY(),"Hôm nay","Còn "&(K12-TODAY())&" ngày")),"") -> Quá hạn 2 ngày
A13: =HYPERLINK("#gid=192210349", "Kế hoạch ngày & IELTS") -> Kế hoạch ngày & IELTS | C13: {=IFERROR(INDEX('Thông tin lớp học'!$G$10:$G$49,MATCH(4,'Thông tin lớp học'!$L$10:$L$49,0)),"")} | E13: {=IFERROR(TEXT(INDEX('Thông tin lớp học'!$I$10:$I$49,MATCH(4,'Thông tin lớp học'!$L$10:$L$49,0)),"hh:mm")&"–"&TEXT(INDEX('Thông tin lớp học'!$J$10:$J$49,MATCH(4,'Thông tin lớp học'!$L$10:$L$49,0)),"hh:mm")&" "&INDEX('Thông tin lớp học'!$K$10:$K$49,MATCH(4,'Thông tin lớp học'!$L$10:$L$49,0)),"")} | G13: {=IFERROR(INDEX('Bảng theo dõi bài tập'!$A$23:$A$72,MATCH(4,'Bảng theo dõi bài tập'!$K$23:$K$72,0))&": "&INDEX('Bảng theo dõi bài tập'!$B$23:$B$72,MATCH(4,'Bảng theo dõi bài tập'!$K$23:$K$72,0)),"")} -> Lập trình C++: Dự án quản lý sinh viên | K13: {=IFERROR(INDEX('Bảng theo dõi bài tập'!$G$23:$G$72,MATCH(4,'Bảng theo dõi bài tập'!$K$23:$K$72,0)),"")} -> 46307 | M13: =IFERROR(IF(K13-TODAY()<0,"Quá hạn "&(TODAY()-K13)&" ngày",IF(K13=TODAY(),"Hôm nay","Còn "&(K13-TODAY())&" ngày")),"") -> Còn 1 ngày
A14: =HYPERLINK("#gid=1115800590","Bảng theo dõi chuyên cần") -> Bảng theo dõi chuyên cần | C14: {=IFERROR(INDEX('Thông tin lớp học'!$G$10:$G$49,MATCH(5,'Thông tin lớp học'!$L$10:$L$49,0)),"")} | E14: {=IFERROR(TEXT(INDEX('Thông tin lớp học'!$I$10:$I$49,MATCH(5,'Thông tin lớp học'!$L$10:$L$49,0)),"hh:mm")&"–"&TEXT(INDEX('Thông tin lớp học'!$J$10:$J$49,MATCH(5,'Thông tin lớp học'!$L$10:$L$49,0)),"hh:mm")&" "&INDEX('Thông tin lớp học'!$K$10:$K$49,MATCH(5,'Thông tin lớp học'!$L$10:$L$49,0)),"")} | G14: {=IFERROR(INDEX('Bảng theo dõi bài tập'!$A$23:$A$72,MATCH(5,'Bảng theo dõi bài tập'!$K$23:$K$72,0))&": "&INDEX('Bảng theo dõi bài tập'!$B$23:$B$72,MATCH(5,'Bảng theo dõi bài tập'!$K$23:$K$72,0)),"")} -> Triết học Mác-Lênin: Kiểm tra trắc nghiệm chương 2 | K14: {=IFERROR(INDEX('Bảng theo dõi bài tập'!$G$23:$G$72,MATCH(5,'Bảng theo dõi bài tập'!$K$23:$K$72,0)),"")} -> 46309 | M14: =IFERROR(IF(K14-TODAY()<0,"Quá hạn "&(TODAY()-K14)&" ngày",IF(K14=TODAY(),"Hôm nay","Còn "&(K14-TODAY())&" ngày")),"") -> Còn 3 ngày
A15: =HYPERLINK("#gid=1072707331","Danh sách tài liệu đọc") -> Danh sách tài liệu đọc | G15: {=IFERROR(INDEX('Bảng theo dõi bài tập'!$A$23:$A$72,MATCH(6,'Bảng theo dõi bài tập'!$K$23:$K$72,0))&": "&INDEX('Bảng theo dõi bài tập'!$B$23:$B$72,MATCH(6,'Bảng theo dõi bài tập'!$K$23:$K$72,0)),"")} -> Kỹ năng mềm: Dự án kế hoạch phát triển cá nhân | K15: {=IFERROR(INDEX('Bảng theo dõi bài tập'!$G$23:$G$72,MATCH(6,'Bảng theo dõi bài tập'!$K$23:$K$72,0)),"")} -> 46315 | M15: =IFERROR(IF(K15-TODAY()<0,"Quá hạn "&(TODAY()-K15)&" ngày",IF(K15=TODAY(),"Hôm nay","Còn "&(K15-TODAY())&" ngày")),"") -> Còn 9 ngày
A16: =HYPERLINK("#gid=1772888216","Habit Tracker") -> Habit Tracker
A17: =HYPERLINK("#gid=128822238","Quản lý giáo trình") -> Quản lý giáo trình | C17: Thói quen hôm nay | G17: 🎯 TIẾN ĐỘ NHIỆM VỤ & IELTS HÔM NAY
A18: =HYPERLINK("#gid=2031529572","Dữ liệu") -> Dữ liệu | C18: =IF('Habit Tracker'!A26="","",'Habit Tracker'!A26) -> [Sức khỏe] Dậy sớm trước 7h sáng | F18: {=IF(C18="","",IF(AND('Habit Tracker'!$B$3=YEAR(TODAY()),'Habit Tracker'!$B$4=MONTH(TODAY())),IF(OR(INDEX('Habit Tracker'!$B$26:$AF$40,1,DAY(TODAY()))="✔",INDEX('Habit Tracker'!$B$26:$AF$40,1,DAY(TODAY()))=TRUE),"✔","○"),"–"))} -> ○ | G18: Nhiệm vụ hôm nay | I18: Tiến độ hoàn thành | K18: Thời gian kế hoạch | M18: Band IELTS trung bình
C19: =IF('Habit Tracker'!A27="","",'Habit Tracker'!A27) -> [Sức khỏe] Uống đủ 2 lít nước | F19: {=IF(C19="","",IF(AND('Habit Tracker'!$B$3=YEAR(TODAY()),'Habit Tracker'!$B$4=MONTH(TODAY())),IF(OR(INDEX('Habit Tracker'!$B$26:$AF$40,2,DAY(TODAY()))="✔",INDEX('Habit Tracker'!$B$26:$AF$40,2,DAY(TODAY()))=TRUE),"✔","○"),"–"))} -> ○ | G19: =COUNTIF('Nhật ký nhiệm vụ'!$B$7:$B$991, TODAY()) -> 0 | I19: =IF(COUNTIF('Nhật ký nhiệm vụ'!$B$7:$B$991, TODAY())=0, 0, COUNTIFS('Nhật ký nhiệm vụ'!$B$7:$B$991, TODAY(), 'Nhật ký nhiệm vụ'!$C$7:$C$991, TRUE)/COUNTIF('Nhật ký nhiệm vụ'!$B$7:$B$991, TODAY())) -> 0 | K19: =TEXT(SUMIFS('Nhật ký nhiệm vụ'!$J$7:$J$991, 'Nhật ký nhiệm vụ'!$B$7:$B$991, TODAY()), "#,##0") & " phút" -> 0 phút | M19: ="Band " & 'Kế hoạch ngày & IELTS'!$K$3 -> Band 7,1
C20: =IF('Habit Tracker'!A28="","",'Habit Tracker'!A28) -> [Sức khỏe] Tập thể dục 30 phút | F20: {=IF(C20="","",IF(AND('Habit Tracker'!$B$3=YEAR(TODAY()),'Habit Tracker'!$B$4=MONTH(TODAY())),IF(OR(INDEX('Habit Tracker'!$B$26:$AF$40,3,DAY(TODAY()))="✔",INDEX('Habit Tracker'!$B$26:$AF$40,3,DAY(TODAY()))=TRUE),"✔","○"),"–"))} -> ○ | G20: =IFERROR(__xludf.DUMMYFUNCTION("SPARKLINE(IF(COUNTIF('Nhật ký nhiệm vụ'!$B$7:$B$991, TODAY())=0, 0, COUNTIFS('Nhật ký nhiệm vụ'!$B$7:$B$991, TODAY(), 'Nhật ký nhiệm vụ'!$C$7:$C$991, TRUE)/COUNTIF('Nhật ký nhiệm vụ'!$B$7:$B$991, TODAY())), {""charttype"",""bar""; ""max"",1; ""color1"","""&"#2e7d32""})"),"") | K20: ="Đã xong " & COUNTIFS('Nhật ký nhiệm vụ'!$B$7:$B$991, TODAY(), 'Nhật ký nhiệm vụ'!$C$7:$C$991, TRUE) & "/" & COUNTIF('Nhật ký nhiệm vụ'!$B$7:$B$991, TODAY()) & " việc • " & TEXT(SUMIFS('Nhật ký nhiệm vụ'!$J$7:$J$991, 'Nhật ký nhiệm vụ'!$B$7:$B$991, TODAY(), 'Nhật ký nhiệm vụ'!$C$7:$C$991, TRUE), "#,##0") & " phút hoàn tất" -> Đã xong 0/0 việc • 0 phút hoàn tất
C21: =IF('Habit Tracker'!A29="","",'Habit Tracker'!A29) -> [Sức khỏe] Ngủ đủ 7-8 tiếng | F21: {=IF(C21="","",IF(AND('Habit Tracker'!$B$3=YEAR(TODAY()),'Habit Tracker'!$B$4=MONTH(TODAY())),IF(OR(INDEX('Habit Tracker'!$B$26:$AF$40,4,DAY(TODAY()))="✔",INDEX('Habit Tracker'!$B$26:$AF$40,4,DAY(TODAY()))=TRUE),"✔","○"),"–"))} -> ○ | G21: ⚡ LIÊN KẾT NHANH ĐẾN CÁC TRANG TÍNH | K21: 📌 NHIỆM VỤ TIÊU BIỂU TRONG NGÀY
C22: =IF('Habit Tracker'!A30="","",'Habit Tracker'!A30) -> [Học tập] Đọc 15 trang sách | F22: {=IF(C22="","",IF(AND('Habit Tracker'!$B$3=YEAR(TODAY()),'Habit Tracker'!$B$4=MONTH(TODAY())),IF(OR(INDEX('Habit Tracker'!$B$26:$AF$40,5,DAY(TODAY()))="✔",INDEX('Habit Tracker'!$B$26:$AF$40,5,DAY(TODAY()))=TRUE),"✔","○"),"–"))} -> ○ | G22: 📋 Nhật ký nhiệm vụ | I22: 🎯 Kế hoạch & IELTS | K22: {=IFERROR(INDEX('Nhật ký nhiệm vụ'!$H$7:$H$991, MATCH(TODAY(), 'Nhật ký nhiệm vụ'!$B$7:$B$991, 0)) & " (" & TEXT(INDEX('Nhật ký nhiệm vụ'!$D$7:$D$991, MATCH(TODAY(), 'Nhật ký nhiệm vụ'!$B$7:$B$991, 0)), "hh:mm") & "–" & TEXT(INDEX('Nhật ký nhiệm vụ'!$E$7:$E$991, MATCH(TODAY(), 'Nhật ký nhiệm vụ'!$B$7:$B$991, 0)), "hh:mm") & ")", "Không có nhiệm vụ hôm nay 🎉")} -> Không có nhiệm vụ hôm nay 🎉
C23: =IF('Habit Tracker'!A31="","",'Habit Tracker'!A31) -> [Học tập] Học từ vựng tiếng Anh 15 phút | F23: {=IF(C23="","",IF(AND('Habit Tracker'!$B$3=YEAR(TODAY()),'Habit Tracker'!$B$4=MONTH(TODAY())),IF(OR(INDEX('Habit Tracker'!$B$26:$AF$40,6,DAY(TODAY()))="✔",INDEX('Habit Tracker'!$B$26:$AF$40,6,DAY(TODAY()))=TRUE),"✔","○"),"–"))} -> ○ | G23: ✅ Việc cần làm | I23: 📅 Xem Lịch tuần | K23: {="Mục tiêu: " & 'Kế hoạch ngày & IELTS'!$M$3 & " • Bài gần nhất: " & INDEX('Kế hoạch ngày & IELTS'!$J$7:$J$14, COUNTA('Kế hoạch ngày & IELTS'!$J$7:$J$14)) & " Band " & INDEX('Kế hoạch ngày & IELTS'!$M$7:$M$14, COUNTA('Kế hoạch ngày & IELTS'!$M$7:$M$14))} -> Mục tiêu: 7.5 Overall • Bài gần nhất: Speaking Band 7
C24: =IF('Habit Tracker'!A32="","",'Habit Tracker'!A32) -> [Học tập] Ôn lại bài trên lớp | F24: {=IF(C24="","",IF(AND('Habit Tracker'!$B$3=YEAR(TODAY()),'Habit Tracker'!$B$4=MONTH(TODAY())),IF(OR(INDEX('Habit Tracker'!$B$26:$AF$40,7,DAY(TODAY()))="✔",INDEX('Habit Tracker'!$B$26:$AF$40,7,DAY(TODAY()))=TRUE),"✔","○"),"–"))} -> ○
C25: =IF('Habit Tracker'!A33="","",'Habit Tracker'!A33) -> [Học tập] Không dùng điện thoại trước khi ngủ | F25: {=IF(C25="","",IF(AND('Habit Tracker'!$B$3=YEAR(TODAY()),'Habit Tracker'!$B$4=MONTH(TODAY())),IF(OR(INDEX('Habit Tracker'!$B$26:$AF$40,8,DAY(TODAY()))="✔",INDEX('Habit Tracker'!$B$26:$AF$40,8,DAY(TODAY()))=TRUE),"✔","○"),"–"))} -> ○ | G25: Tổng quan chuyên cần
C26: =IF('Habit Tracker'!A34="","",'Habit Tracker'!A34) -> [Lối sống] Viết nhật ký & Kế hoạch ngày mới | F26: {=IF(C26="","",IF(AND('Habit Tracker'!$B$3=YEAR(TODAY()),'Habit Tracker'!$B$4=MONTH(TODAY())),IF(OR(INDEX('Habit Tracker'!$B$26:$AF$40,9,DAY(TODAY()))="✔",INDEX('Habit Tracker'!$B$26:$AF$40,9,DAY(TODAY()))=TRUE),"✔","○"),"–"))} -> ○ | G26: Có mặt ✔ | I26: Vắng ✘ | K26: Đi muộn ⏳ | M26: Tỷ lệ
C27: =IF('Habit Tracker'!A35="","",'Habit Tracker'!A35) -> [Lối sống] Thiền / hít thở sâu 10 phút | F27: {=IF(C27="","",IF(AND('Habit Tracker'!$B$3=YEAR(TODAY()),'Habit Tracker'!$B$4=MONTH(TODAY())),IF(OR(INDEX('Habit Tracker'!$B$26:$AF$40,10,DAY(TODAY()))="✔",INDEX('Habit Tracker'!$B$26:$AF$40,10,DAY(TODAY()))=TRUE),"✔","○"),"–"))} -> ○ | G27: ='Bảng theo dõi chuyên cần'!B13 -> 32 | I27: ='Bảng theo dõi chuyên cần'!C13 -> 3 | K27: ='Bảng theo dõi chuyên cần'!D13 -> 3 | M27: ='Bảng theo dõi chuyên cần'!E13 -> 0.92105263
C28: =IF('Habit Tracker'!A36="","",'Habit Tracker'!A36) -> [Lối sống] Ăn đủ 3 bữa / không bỏ bữa | F28: {=IF(C28="","",IF(AND('Habit Tracker'!$B$3=YEAR(TODAY()),'Habit Tracker'!$B$4=MONTH(TODAY())),IF(OR(INDEX('Habit Tracker'!$B$26:$AF$40,11,DAY(TODAY()))="✔",INDEX('Habit Tracker'!$B$26:$AF$40,11,DAY(TODAY()))=TRUE),"✔","○"),"–"))} -> ○ | G28: =IF('Bảng theo dõi chuyên cần'!$D$4="✅ An toàn", "Đánh giá: ✅ Chuyên cần tốt (Tất cả các môn ≥ 80%)", "Đánh giá: " & 'Bảng theo dõi chuyên cần'!$D$4) -> Đánh giá: ⚠️ Tiếng Anh giao tiếp: 67% (< 80%)

Sheet Kế hoạch ngày & IELTS
B1: KẾ HOẠCH NGÀY & LUYỆN THI IELTS | N1: ⌂ Về Dashboard
B2: HÔM NAY | D2: TỔNG THỜI GIAN HỌC | F2: TỶ LỆ HOÀN THÀNH | I2: TỔNG BUỔI LUYỆN IELTS | K2: BAND ĐIỂM TRUNG BÌNH | M2: MỤC TIÊU IELTS
B3: =TODAY() -> 46306 | D3: =SUMIFS('Nhật ký nhiệm vụ'!J:J, 'Nhật ký nhiệm vụ'!B:B, B3) -> 0 | F3: =IF(COUNTIFS('Nhật ký nhiệm vụ'!B:B, B3, 'Nhật ký nhiệm vụ'!H:H, "?*")=0, 0, COUNTIFS('Nhật ký nhiệm vụ'!B:B, B3, 'Nhật ký nhiệm vụ'!C:C, TRUE)/COUNTIFS('Nhật ký nhiệm vụ'!B:B, B3, 'Nhật ký nhiệm vụ'!H:H, "?*")) -> 0 | I3: =COUNTIF(J7:J20, "?*") -> 8 | K3: =IFERROR(ROUND(AVERAGE(M7:M20), 1), 7) -> 7.1 | M3: 7.5 Overall
B4: =TEXT(TODAY(), "dddd") -> Chủ Nhật | D4: ="Đã xong: " & TEXT(SUMIFS('Nhật ký nhiệm vụ'!J:J, 'Nhật ký nhiệm vụ'!B:B, B3, 'Nhật ký nhiệm vụ'!C:C, TRUE), "#,##0") & " phút" -> Đã xong: 0 phút | F4: ="Đã xong " & COUNTIFS('Nhật ký nhiệm vụ'!B:B, B3, 'Nhật ký nhiệm vụ'!C:C, TRUE) & " / " & COUNTIFS('Nhật ký nhiệm vụ'!B:B, B3, 'Nhật ký nhiệm vụ'!H:H, "?*") & " việc" -> Đã xong 0 / 0 việc | I4: 4 kỹ năng tích hợp | K4: Từ các bài kiểm tra gần nhất | M4: Target học kỳ 1
B6: Hoàn thành | C6: Khung giờ | D6: Phân loại | E6: Nhiệm vụ | F6: Mức ưu tiên | G6: Thời lượng (phút) | I6: Ngày | J6: Kỹ năng | K6: Tài liệu | L6: Dạng bài | M6: Điểm / Band | N6: Phân tích lỗi sai & Ghi chú
B7: =IFERROR(__xludf.DUMMYFUNCTION("IFERROR(LET(data, FILTER('Nhật ký nhiệm vụ'!C7:J100, 'Nhật ký nhiệm vụ'!B7:B100=B3), HSTACK(MAP(CHOOSECOLS(data, 1), LAMBDA(c, IF(c=TRUE, ""✔"", ""—""))), MAP(CHOOSECOLS(data, 2), CHOOSECOLS(data, 3), LAMBDA(s, e, IF(OR(s="""", e=""""), """", TEXT(s, ""hh"&":mm"") & "" - "" & TEXT(e, ""hh:mm"")))), CHOOSECOLS(data, 4, 6, 7, 8))), """")"),"") | C7: =IFERROR(__xludf.DUMMYFUNCTION("""COMPUTED_VALUE"""),"") | D7: =IFERROR(__xludf.DUMMYFUNCTION("""COMPUTED_VALUE"""),"") | I7: 2026-09-28 | J7: Listening | K7: Cambridge IELTS 18 Test 1 | L7: Section 1 & 2 (Form & Map) | M7: 7.5 | N7: Sai 3 câu do lỡ nhịp từ khóa số nhiều; cần lưu ý phát âm nối âm.
I8: 2026-09-29 | J8: Reading | K8: Cambridge IELTS 18 Test 1 | L8: Passage 2: True/False/Not Given | M8: 7 | N8: Dễ nhầm lẫn giữa False và Not Given; cần bám sát bằng chứng bài đọc.
I9: 2026-09-30 | J9: Writing | K9: Makkar IELTS Writing Task 2 | L9: Opinion Essay: Technology | M9: 6.5 | N9: Luận điểm thân bài 2 chưa đào sâu; thiếu từ vựng học thuật collocation.
I10: 2026-10-01 | J10: Speaking | K10: IELTS Forecast Q3/Q4 | L10: Part 2: Describe a helpful person | M10: 6.5 | N10: Còn ngập ngừng khi triển khai ý mở rộng; cần trau chuốt fluency & coherence.
I11: 2026-10-02 | J11: Listening | K11: Cambridge IELTS 18 Test 2 | L11: Section 3: Multiple Choice | M11: 8 | N11: Nhận diện bẫy thông tin gây nhiễu rất tốt; kỹ năng take note từ khóa hiệu quả.
I12: 2026-10-03 | J12: Writing | K12: Cambridge IELTS 17 Test 3 | L12: Task 1: Mixed Chart (Bar & Line) | M12: 7 | N12: Phần Overview rõ ràng; cần chú ý đa dạng cấu trúc so sánh tăng giảm.
I13: 46300 | J13: Writing | K13: Cambridge IELTS 18 Test 3 | L13: Task 2: Discussion Essay (Education) | M13: 7 | N13: Ý tưởng mạch lạc; cần tăng cường collocations học thuật để chạm mốc Band 7.5.
I14: 46301 | J14: Speaking | K14: IELTS Forecast Q3/Q4 | L14: Part 3: Discussion on Technology & Life | M14: 7 | N14: Phản xạ câu hỏi khó tốt; chú ý kiểm soát ngữ điệu và phát âm âm cuối.
I15: BẢNG PHÂN TÍCH BAND ĐIỂM THEO 4 KỸ NĂNG
I16: Kỹ năng | K16: Band TB | M16: Trạng thái & Định hướng
I17: Listening | K17: =IFERROR(ROUND(AVERAGEIF($J$7:$J$14, "Listening", $M$7:$M$14), 1), "-") -> 7.8 | M17: =IF(K17="-", "-", IF(K17>=7.5, "Rất tốt - Duy trì", "Cần luyện thêm")) -> Rất tốt - Duy trì
I18: Reading | K18: =IFERROR(ROUND(AVERAGEIF($J$7:$J$14, "Reading", $M$7:$M$14), 1), "-") -> 7 | M18: =IF(K18="-", "-", IF(K18>=7.5, "Rất tốt - Duy trì", "Cần luyện thêm")) -> Cần luyện thêm
I19: Writing | K19: =IFERROR(ROUND(AVERAGEIF($J$7:$J$14, "Writing", $M$7:$M$14), 1), "-") -> 6.8 | M19: =IF(K19="-", "-", IF(K19>=7.5, "Rất tốt - Duy trì", "Cần luyện thêm")) -> Cần luyện thêm
I20: Speaking | K20: =IFERROR(ROUND(AVERAGEIF($J$7:$J$14, "Speaking", $M$7:$M$14), 1), "-") -> 6.8 | M20: =IF(K20="-", "-", IF(K20>=7.5, "Rất tốt - Duy trì", "Cần luyện thêm")) -> Cần luyện thêm
I21: Overall Band | K21: =IFERROR(ROUND(AVERAGE(K17:K20), 1), "-") -> 7.1 | M21: =IF(OR(K21="-", K21=""), "-", IF(K21>=7.5, "Đạt mục tiêu Target 7.5 🎯", "Cách Target 7.5: " & TEXT(7.5-K21, "0.0") & " band")) -> Cách Target 7.5: 0,4 band
B22: THỐNG KÊ TIẾN ĐỘ TÍCH LŨY (TOÀN THỜI GIAN)
B23: TỔNG GIỜ LUYỆN IELTS TÍCH LŨY | E23: TỶ LỆ HOÀN THÀNH TÍCH LŨY
B24: =ROUND(SUMIFS('Nhật ký nhiệm vụ'!J:J, 'Nhật ký nhiệm vụ'!F:F, "IELTS")/60, 1) -> 8 | E24: =IF(COUNTIF('Nhật ký nhiệm vụ'!H7:H100, "?*")=0, 0, COUNTIF('Nhật ký nhiệm vụ'!C7:C100, TRUE)/COUNTIF('Nhật ký nhiệm vụ'!H7:H100, "?*")) -> 0.6
B25: ="Đã tích lũy " & TEXT(SUMIFS('Nhật ký nhiệm vụ'!J:J, 'Nhật ký nhiệm vụ'!F:F, "IELTS"), "#,##0") & " phút luyện tập" -> Đã tích lũy 480 phút luyện tập | E25: =IFERROR(__xludf.DUMMYFUNCTION("SPARKLINE(E24, {""charttype"",""bar""; ""max"",1; ""color1"",""#1a73e8""})"),"")

Sheet Nhật ký nhiệm vụ
A1: 📋 NHẬT KÝ NHIỆM VỤ HÀNG NGÀY | J1: ⌂ Về Dashboard
A3: TỔNG NHIỆM VỤ | D3: ĐÃ HOÀN THÀNH | G3: TỶ LỆ HOÀN THÀNH | K3: TỔNG THỜI GIAN HỌC
A4: =COUNTIF(H7:H986, "?*") -> 35 | D4: =COUNTIFS(H7:H986, "?*", C7:C986, TRUE) + COUNTIFS(H7:H986, "?*", N7:N986, "Đã hoàn thành bù") -> 28 | G4: =IF(A4=0, 0, D4/A4) -> 0.8 | K4: =SUM(J7:J986) -> 6435
A6: Mã Task | B6: Ngày | C6: Hoàn thành | D6: Bắt đầu | E6: Kết thúc | F6: Phân loại | G6: Kỹ năng IELTS | H6: Nhiệm vụ | I6: Mức ưu tiên | J6: Thời lượng (phút) | K6: Ghi chú | L6: Hạn chót | M6: Bù cho Task | N6: Trạng thái
A7: =IF(OR(B7<>"", H7<>""), "T" & TEXT(ROW()-6, "00"), "") -> T01 | B7: 46299 | C7: TRUE | D7: 0.3125 | E7: 0.35416667 | F7: IELTS | G7: Listening | H7: Luyện nghe Cam 18 Test 1 Section 1 & 2 | I7: Cao | J7: =IFERROR(IF(AND(D7<>"", E7<>""), ROUND(MOD(E7 - D7, 1) * 1440,0), IFERROR(VLOOKUP(H7, 'Dữ liệu'!$X$4:$AA$15, 4, FALSE), "")), "") -> 60 | L7: =IF(B7="", "", B7) -> 46299 | N7: =IF(OR(B7="", H7=""), "", IF(C7=TRUE, IF(OR(M7<>"", ISNUMBER(SEARCH("bù", K7&" "&H7)), ISNUMBER(SEARCH("dời", K7&" "&H7)), AND(ISNUMBER(L7), ISNUMBER(B7), L7<>"", B7>L7)), "Hoàn thành bù", "Hoàn thành"), IF((COUNTIFS($M$7:$M$50, A7, $C$7:$C$50, TRUE) + COUNTIFS($M$7:$M$50, IFERROR(INDEX($A$7:$A$50, MATCH(A7, $M$7:$M$50, 0)), "###"), $C$7:$C$50, TRUE) + COUNTIFS($M$7:$M$50, IFERROR(INDEX($A$7:$A$50, MATCH(IFERROR(INDEX($A$7:$A$50, MATCH(A7, $M$7:$M$50, 0)), "###"), $M$7:$M$50, 0)), "###"), $C$7:$C$50, TRUE) + COUNTIFS($M$7:$M$50, IFERROR(INDEX($A$7:$A$50, MATCH(IFERROR(INDEX($A$7:$A$50, MATCH(IFERROR(INDEX($A$7:$A$50, MATCH(A7, $M$7:$M$50, 0)), "###"), $M$7:$M$50, 0)), "###"), $M$7:$M$50, 0)), "###"), $C$7:$C$50, TRUE))>0, "Đã hoàn thành bù", IF(OR(ISNUMBER(SEARCH("dời", K7)), ISNUMBER(SEARCH("hoãn", K7))), "Dời lịch", IF(AND(ISNUMBER(IF(L7<>"", L7, B7)), IF(L7<>"", L7, B7)<TODAY()), "Quá hạn", "Đang thực hiện"))))) -> Hoàn thành
A8: =IF(OR(B8<>"", H8<>""), "T" & TEXT(ROW()-6, "00"), "") -> T02 | B8: 46300 | C8: TRUE | D8: 0.29166667 | E8: 0.64583333 | F8: Làm thêm | H8: Làm 250 dòng Properties | I8: Cao | J8: =IFERROR(IF(AND(D8<>"", E8<>""), ROUND(MOD(E8 - D8, 1) * 1440,0), IFERROR(VLOOKUP(H8, 'Dữ liệu'!$X$4:$AA$15, 4, FALSE), "")), "") -> 510 | L8: =IF(B8="", "", B8) -> 46300 | N8: =IF(OR(B8="", H8=""), "", IF(C8=TRUE, IF(OR(M8<>"", ISNUMBER(SEARCH("bù", K8&" "&H8)), ISNUMBER(SEARCH("dời", K8&" "&H8)), AND(ISNUMBER(L8), ISNUMBER(B8), L8<>"", B8>L8)), "Hoàn thành bù", "Hoàn thành"), IF((COUNTIFS($M$7:$M$50, A8, $C$7:$C$50, TRUE) + COUNTIFS($M$7:$M$50, IFERROR(INDEX($A$7:$A$50, MATCH(A8, $M$7:$M$50, 0)), "###"), $C$7:$C$50, TRUE) + COUNTIFS($M$7:$M$50, IFERROR(INDEX($A$7:$A$50, MATCH(IFERROR(INDEX($A$7:$A$50, MATCH(A8, $M$7:$M$50, 0)), "###"), $M$7:$M$50, 0)), "###"), $C$7:$C$50, TRUE) + COUNTIFS($M$7:$M$50, IFERROR(INDEX($A$7:$A$50, MATCH(IFERROR(INDEX($A$7:$A$50, MATCH(IFERROR(INDEX($A$7:$A$50, MATCH(A8, $M$7:$M$50, 0)), "###"), $M$7:$M$50, 0)), "###"), $M$7:$M$50, 0)), "###"), $C$7:$C$50, TRUE))>0, "Đã hoàn thành bù", IF(OR(ISNUMBER(SEARCH("dời", K8)), ISNUMBER(SEARCH("hoãn", K8))), "Dời lịch", IF(AND(ISNUMBER(IF(L8<>"", L8, B8)), IF(L8<>"", L8, B8)<TODAY()), "Quá hạn", "Đang thực hiện"))))) -> Hoàn thành
A9: =IF(OR(B9<>"", H9<>""), "T" & TEXT(ROW()-6, "00"), "") -> T03 | B9: 46300 | C9: TRUE | D9: 0.66666667 | E9: 0.75 | F9: Học tập | H9: Đi học thêm Ielts | I9: Cao | J9: =IFERROR(IF(AND(D9<>"", E9<>""), ROUND(MOD(E9 - D9, 1) * 1440,0), IFERROR(VLOOKUP(H9, 'Dữ liệu'!$X$4:$AA$15, 4, FALSE), "")), "") -> 120 | L9: =IF(B9="", "", B9) -> 46300 | N9: =IF(OR(B9="", H9=""), "", IF(C9=TRUE, IF(OR(M9<>"", ISNUMBER(SEARCH("bù", K9&" "&H9)), ISNUMBER(SEARCH("dời", K9&" "&H9)), AND(ISNUMBER(L9), ISNUMBER(B9), L9<>"", B9>L9)), "Hoàn thành bù", "Hoàn thành"), IF((COUNTIFS($M$7:$M$50, A9, $C$7:$C$50, TRUE) + COUNTIFS($M$7:$M$50, IFERROR(INDEX($A$7:$A$50, MATCH(A9, $M$7:$M$50, 0)), "###"), $C$7:$C$50, TRUE) + COUNTIFS($M$7:$M$50, IFERROR(INDEX($A$7:$A$50, MATCH(IFERROR(INDEX($A$7:$A$50, MATCH(A9, $M$7:$M$50, 0)), "###"), $M$7:$M$50, 0)), "###"), $C$7:$C$50, TRUE) + COUNTIFS($M$7:$M$50, IFERROR(INDEX($A$7:$A$50, MATCH(IFERROR(INDEX($A$7:$A$50, MATCH(IFERROR(INDEX($A$7:$A$50, MATCH(A9, $M$7:$M$50, 0)), "###"), $M$7:$M$50, 0)), "###"), $M$7:$M$50, 0)), "###"), $C$7:$C$50, TRUE))>0, "Đã hoàn thành bù", IF(OR(ISNUMBER(SEARCH("dời", K9)), ISNUMBER(SEARCH("hoãn", K9))), "Dời lịch", IF(AND(ISNUMBER(IF(L9<>"", L9, B9)), IF(L9<>"", L9, B9)<TODAY()), "Quá hạn", "Đang thực hiện"))))) -> Hoàn thành
A10: =IF(OR(B10<>"", H10<>""), "T" & TEXT(ROW()-6, "00"), "") -> T04 | B10: 46300 | C10: TRUE | D10: 0.77083333 | E10: 0.85416667 | F10: Cá nhân | H10: Đi ăn teambuilding với công ty | I10: Cao | J10: =IFERROR(IF(AND(D10<>"", E10<>""), ROUND(MOD(E10 - D10, 1) * 1440,0), IFERROR(VLOOKUP(H10, 'Dữ liệu'!$X$4:$AA$15, 4, FALSE), "")), "") -> 120 | L10: =IF(B10="", "", B10) -> 46300 | N10: {=IF(OR(B10="", H10=""), "", IF(C10=TRUE, IF(OR(M10<>"", ISNUMBER(SEARCH("bù", K10&" "&H10)), ISNUMBER(SEARCH("dời", K10&" "&H10)), AND(ISNUMBER(L10), ISNUMBER(B10), L10<>"", B10>L10)), "Hoàn thành bù", "Hoàn thành"), IF((COUNTIFS($M$7:$M$50, A10, $C$7:$C$50, TRUE) + COUNTIFS($M$7:$M$50, IFERROR(INDEX($A$7:$A$50, MATCH(A10, $M$7:$M$50, 0)), "###"), $C$7:$C$50, TRUE) + COUNTIFS($M$7:$M$50, IFERROR(INDEX($A$7:$A$50, MATCH(IFERROR(INDEX($A$7:$A$50, MATCH(A10, $M$7:$M$50, 0)), "###"), $M$7:$M$50, 0)), "###"), $C$7:$C$50, TRUE) + COUNTIFS($M$7:$M$50, IFERROR(INDEX($A$7:$A$50, MATCH(IFERROR(INDEX($A$7:$A$50, MATCH(IFERROR(INDEX($A$7:$A$50, MATCH(A10, $M$7:$M$50, 0)), "###"), $M$7:$M$50, 0)), "###"), $M$7:$M$50, 0)), "###"), $C$7:$C$50, TRUE))>0, "Đã hoàn thành bù", IF(OR(ISNUMBER(SEARCH("dời", K10)), ISNUMBER(SEARCH("hoãn", K10))), "Dời lịch", IF(AND(ISNUMBER(IF(L10<>"", L10, B9)), IF(L10<>"", L10, B10)<TODAY()), "Quá hạn", "Đang thực hiện")))))} -> Hoàn thành
A11: =IF(OR(B11<>"", H11<>""), "T" & TEXT(ROW()-6, "00"), "") -> T05 | B11: 46300 | C11: FALSE | D11: 0.875 | E11: 0.95833333 | F11: IELTS | G11: Vocabulary | H11: Học từ vựng và làm bài tập chủ đề mua sắm | I11: Cao | J11: =IFERROR(IF(AND(D11<>"", E11<>""), ROUND(MOD(E11 - D11, 1) * 1440,0), IFERROR(VLOOKUP(H11, 'Dữ liệu'!$X$4:$AA$15, 4, FALSE), "")), "") -> 120 | K11: Đã hoàn thành 2/8 bài tập | L11: =IF(B11="", "", B11) -> 46300 | N11: =IF(OR(B11="", H11=""), "", IF(C11=TRUE, IF(OR(M11<>"", ISNUMBER(SEARCH("bù", K11&" "&H11)), ISNUMBER(SEARCH("dời", K11&" "&H11)), AND(ISNUMBER(L11), ISNUMBER(B11), L11<>"", B11>L11)), "Hoàn thành bù", "Hoàn thành"), IF((COUNTIFS($M$7:$M$50, A11, $C$7:$C$50, TRUE) + COUNTIFS($M$7:$M$50, IFERROR(INDEX($A$7:$A$50, MATCH(A11, $M$7:$M$50, 0)), "###"), $C$7:$C$50, TRUE) + COUNTIFS($M$7:$M$50, IFERROR(INDEX($A$7:$A$50, MATCH(IFERROR(INDEX($A$7:$A$50, MATCH(A11, $M$7:$M$50, 0)), "###"), $M$7:$M$50, 0)), "###"), $C$7:$C$50, TRUE) + COUNTIFS($M$7:$M$50, IFERROR(INDEX($A$7:$A$50, MATCH(IFERROR(INDEX($A$7:$A$50, MATCH(IFERROR(INDEX($A$7:$A$50, MATCH(A11, $M$7:$M$50, 0)), "###"), $M$7:$M$50, 0)), "###"), $M$7:$M$50, 0)), "###"), $C$7:$C$50, TRUE))>0, "Đã hoàn thành bù", IF(OR(ISNUMBER(SEARCH("dời", K11)), ISNUMBER(SEARCH("hoãn", K11))), "Dời lịch", IF(AND(ISNUMBER(IF(L11<>"", L11, B11)), IF(L11<>"", L11, B11)<TODAY()), "Quá hạn", "Đang thực hiện"))))) -> Đã hoàn thành bù
A12: =IF(OR(B12<>"", H12<>""), "T" & TEXT(ROW()-6, "00"), "") -> T06 | B12: 46301 | C12: TRUE | D12: 0.29166667 | E12: 0.64583333 | F12: Làm thêm | H12: Làm 250 dòng Properties | I12: Cao | J12: =IFERROR(IF(AND(D12<>"", E12<>""), ROUND(MOD(E12 - D12, 1) * 1440,0), IFERROR(VLOOKUP(H12, 'Dữ liệu'!$X$4:$AA$15, 4, FALSE), "")), "") -> 510 | L12: =IF(B12="", "", B12) -> 46301 | N12: =IF(OR(B12="", H12=""), "", IF(C12=TRUE, IF(OR(M12<>"", ISNUMBER(SEARCH("bù", K12&" "&H12)), ISNUMBER(SEARCH("dời", K12&" "&H12)), AND(ISNUMBER(L12), ISNUMBER(B12), L12<>"", B12>L12)), "Hoàn thành bù", "Hoàn thành"), IF((COUNTIFS($M$7:$M$50, A12, $C$7:$C$50, TRUE) + COUNTIFS($M$7:$M$50, IFERROR(INDEX($A$7:$A$50, MATCH(A12, $M$7:$M$50, 0)), "###"), $C$7:$C$50, TRUE) + COUNTIFS($M$7:$M$50, IFERROR(INDEX($A$7:$A$50, MATCH(IFERROR(INDEX($A$7:$A$50, MATCH(A12, $M$7:$M$50, 0)), "###"), $M$7:$M$50, 0)), "###"), $C$7:$C$50, TRUE) + COUNTIFS($M$7:$M$50, IFERROR(INDEX($A$7:$A$50, MATCH(IFERROR(INDEX($A$7:$A$50, MATCH(IFERROR(INDEX($A$7:$A$50, MATCH(A12, $M$7:$M$50, 0)), "###"), $M$7:$M$50, 0)), "###"), $M$7:$M$50, 0)), "###"), $C$7:$C$50, TRUE))>0, "Đã hoàn thành bù", IF(OR(ISNUMBER(SEARCH("dời", K12)), ISNUMBER(SEARCH("hoãn", K12))), "Dời lịch", IF(AND(ISNUMBER(IF(L12<>"", L12, B12)), IF(L12<>"", L12, B12)<TODAY()), "Quá hạn", "Đang thực hiện"))))) -> Hoàn thành
A13: =IF(OR(B13<>"", H13<>""), "T" & TEXT(ROW()-6, "00"), "") -> T07 | B13: 46301 | C13: TRUE | D13: 0.66666667 | E13: 0.70833333 | F13: IELTS | G13: Vocabulary | H13: Làm bài tập 3-8 chủ đề mua sắm | I13: Khẩn cấp | J13: =IFERROR(IF(AND(D13<>"", E13<>""), ROUND(MOD(E13 - D13, 1) * 1440,0), IFERROR(VLOOKUP(H13, 'Dữ liệu'!$X$4:$AA$15, 4, FALSE), "")), "") -> 60 | L13: =IF(B13="", "", B13) -> 46301 | M13: T05 | N13: =IF(OR(B13="", H13=""), "", IF(C13=TRUE, IF(OR(M13<>"", ISNUMBER(SEARCH("bù", K13&" "&H13)), ISNUMBER(SEARCH("dời", K13&" "&H13)), AND(ISNUMBER(L13), ISNUMBER(B13), L13<>"", B13>L13)), "Hoàn thành bù", "Hoàn thành"), IF((COUNTIFS($M$7:$M$50, A13, $C$7:$C$50, TRUE) + COUNTIFS($M$7:$M$50, IFERROR(INDEX($A$7:$A$50, MATCH(A13, $M$7:$M$50, 0)), "###"), $C$7:$C$50, TRUE) + COUNTIFS($M$7:$M$50, IFERROR(INDEX($A$7:$A$50, MATCH(IFERROR(INDEX($A$7:$A$50, MATCH(A13, $M$7:$M$50, 0)), "###"), $M$7:$M$50, 0)), "###"), $C$7:$C$50, TRUE) + COUNTIFS($M$7:$M$50, IFERROR(INDEX($A$7:$A$50, MATCH(IFERROR(INDEX($A$7:$A$50, MATCH(IFERROR(INDEX($A$7:$A$50, MATCH(A13, $M$7:$M$50, 0)), "###"), $M$7:$M$50, 0)), "###"), $M$7:$M$50, 0)), "###"), $C$7:$C$50, TRUE))>0, "Đã hoàn thành bù", IF(OR(ISNUMBER(SEARCH("dời", K13)), ISNUMBER(SEARCH("hoãn", K13))), "Dời lịch", IF(AND(ISNUMBER(IF(L13<>"", L13, B13)), IF(L13<>"", L13, B13)<TODAY()), "Quá hạn", "Đang thực hiện"))))) -> Hoàn thành bù
A14: =IF(OR(B14<>"", H14<>""), "T" & TEXT(ROW()-6, "00"), "") -> T08 | B14: 46301 | C14: FALSE | D14: 0.70833333 | E14: 0.75 | F14: IELTS | G14: Vocabulary | H14: Học từ vựng và làm bài tập chủ đề cửa hàng | I14: Cao | J14: =IFERROR(IF(AND(D14<>"", E14<>""), ROUND(MOD(E14 - D14, 1) * 1440,0), IFERROR(VLOOKUP(H14, 'Dữ liệu'!$X$4:$AA$15, 4, FALSE), "")), "") -> 60 | L14: =IF(B14="", "", B14) -> 46301 | N14: =IF(OR(B14="", H14=""), "", IF(C14=TRUE, IF(OR(M14<>"", ISNUMBER(SEARCH("bù", K14&" "&H14)), ISNUMBER(SEARCH("dời", K14&" "&H14)), AND(ISNUMBER(L14), ISNUMBER(B14), L14<>"", B14>L14)), "Hoàn thành bù", "Hoàn thành"), IF((COUNTIFS($M$7:$M$50, A14, $C$7:$C$50, TRUE) + COUNTIFS($M$7:$M$50, IFERROR(INDEX($A$7:$A$50, MATCH(A14, $M$7:$M$50, 0)), "###"), $C$7:$C$50, TRUE) + COUNTIFS($M$7:$M$50, IFERROR(INDEX($A$7:$A$50, MATCH(IFERROR(INDEX($A$7:$A$50, MATCH(A14, $M$7:$M$50, 0)), "###"), $M$7:$M$50, 0)), "###"), $C$7:$C$50, TRUE) + COUNTIFS($M$7:$M$50, IFERROR(INDEX($A$7:$A$50, MATCH(IFERROR(INDEX($A$7:$A$50, MATCH(IFERROR(INDEX($A$7:$A$50, MATCH(A14, $M$7:$M$50, 0)), "###"), $M$7:$M$50, 0)), "###"), $M$7:$M$50, 0)), "###"), $C$7:$C$50, TRUE))>0, "Đã hoàn thành bù", IF(OR(ISNUMBER(SEARCH("dời", K14)), ISNUMBER(SEARCH("hoãn", K14))), "Dời lịch", IF(AND(ISNUMBER(IF(L14<>"", L14, B14)), IF(L14<>"", L14, B14)<TODAY()), "Quá hạn", "Đang thực hiện"))))) -> Đã hoàn thành bù
A15: =IF(OR(B15<>"", H15<>""), "T" & TEXT(ROW()-6, "00"), "") -> T09 | B15: 46301 | C15: TRUE | D15: 0.75 | E15: 0.875 | F15: Học tập | H15: Theo thời khóa biểu môn học | I15: Cao | J15: =IFERROR(IF(AND(D15<>"", E15<>""), ROUND(MOD(E15 - D15, 1) * 1440,0), IFERROR(VLOOKUP(H15, 'Dữ liệu'!$X$4:$AA$15, 4, FALSE), "")), "") -> 180 | L15: =IF(B15="", "", B15) -> 46301 | N15: =IF(OR(B15="", H15=""), "", IF(C15=TRUE, IF(OR(M15<>"", ISNUMBER(SEARCH("bù", K15&" "&H15)), ISNUMBER(SEARCH("dời", K15&" "&H15)), AND(ISNUMBER(L15), ISNUMBER(B15), L15<>"", B15>L15)), "Hoàn thành bù", "Hoàn thành"), IF((COUNTIFS($M$7:$M$50, A15, $C$7:$C$50, TRUE) + COUNTIFS($M$7:$M$50, IFERROR(INDEX($A$7:$A$50, MATCH(A15, $M$7:$M$50, 0)), "###"), $C$7:$C$50, TRUE) + COUNTIFS($M$7:$M$50, IFERROR(INDEX($A$7:$A$50, MATCH(IFERROR(INDEX($A$7:$A$50, MATCH(A15, $M$7:$M$50, 0)), "###"), $M$7:$M$50, 0)), "###"), $C$7:$C$50, TRUE) + COUNTIFS($M$7:$M$50, IFERROR(INDEX($A$7:$A$50, MATCH(IFERROR(INDEX($A$7:$A$50, MATCH(IFERROR(INDEX($A$7:$A$50, MATCH(A15, $M$7:$M$50, 0)), "###"), $M$7:$M$50, 0)), "###"), $M$7:$M$50, 0)), "###"), $C$7:$C$50, TRUE))>0, "Đã hoàn thành bù", IF(OR(ISNUMBER(SEARCH("dời", K15)), ISNUMBER(SEARCH("hoãn", K15))), "Dời lịch", IF(AND(ISNUMBER(IF(L15<>"", L15, B15)), IF(L15<>"", L15, B15)<TODAY()), "Quá hạn", "Đang thực hiện"))))) -> Hoàn thành
A16: =IF(OR(B16<>"", H16<>""), "T" & TEXT(ROW()-6, "00"), "") -> T10 | B16: 46302 | C16: TRUE | D16: 0.29166667 | E16: 0.64583333 | F16: Làm thêm | H16: Làm 250 dòng Properties | I16: Cao | J16: =IFERROR(IF(AND(D16<>"", E16<>""), ROUND(MOD(E16 - D16, 1) * 1440,0), IFERROR(VLOOKUP(H16, 'Dữ liệu'!$X$4:$AA$15, 4, FALSE), "")), "") -> 510 | L16: =IF(B16="", "", B16) -> 46302 | N16: =IF(OR(B16="", H16=""), "", IF(C16=TRUE, IF(OR(M16<>"", ISNUMBER(SEARCH("bù", K16&" "&H16)), ISNUMBER(SEARCH("dời", K16&" "&H16)), AND(ISNUMBER(L16), ISNUMBER(B16), L16<>"", B16>L16)), "Hoàn thành bù", "Hoàn thành"), IF((COUNTIFS($M$7:$M$50, A16, $C$7:$C$50, TRUE) + COUNTIFS($M$7:$M$50, IFERROR(INDEX($A$7:$A$50, MATCH(A16, $M$7:$M$50, 0)), "###"), $C$7:$C$50, TRUE) + COUNTIFS($M$7:$M$50, IFERROR(INDEX($A$7:$A$50, MATCH(IFERROR(INDEX($A$7:$A$50, MATCH(A16, $M$7:$M$50, 0)), "###"), $M$7:$M$50, 0)), "###"), $C$7:$C$50, TRUE) + COUNTIFS($M$7:$M$50, IFERROR(INDEX($A$7:$A$50, MATCH(IFERROR(INDEX($A$7:$A$50, MATCH(IFERROR(INDEX($A$7:$A$50, MATCH(A16, $M$7:$M$50, 0)), "###"), $M$7:$M$50, 0)), "###"), $M$7:$M$50, 0)), "###"), $C$7:$C$50, TRUE))>0, "Đã hoàn thành bù", IF(OR(ISNUMBER(SEARCH("dời", K16)), ISNUMBER(SEARCH("hoãn", K16))), "Dời lịch", IF(AND(ISNUMBER(IF(L16<>"", L16, B16)), IF(L16<>"", L16, B16)<TODAY()), "Quá hạn", "Đang thực hiện"))))) -> Hoàn thành
A17: =IF(OR(B17<>"", H17<>""), "T" & TEXT(ROW()-6, "00"), "") -> T11 | B17: 46302 | C17: TRUE | D17: 0.66666667 | E17: 0.75 | F17: Học tập | H17: Đi học thêm Ielts | I17: Cao | J17: =IFERROR(IF(AND(D17<>"", E17<>""), ROUND(MOD(E17 - D17, 1) * 1440,0), IFERROR(VLOOKUP(H17, 'Dữ liệu'!$X$4:$AA$15, 4, FALSE), "")), "") -> 120 | L17: =IF(B17="", "", B17) -> 46302 | N17: =IF(OR(B17="", H17=""), "", IF(C17=TRUE, IF(OR(M17<>"", ISNUMBER(SEARCH("bù", K17&" "&H17)), ISNUMBER(SEARCH("dời", K17&" "&H17)), AND(ISNUMBER(L17), ISNUMBER(B17), L17<>"", B17>L17)), "Hoàn thành bù", "Hoàn thành"), IF((COUNTIFS($M$7:$M$50, A17, $C$7:$C$50, TRUE) + COUNTIFS($M$7:$M$50, IFERROR(INDEX($A$7:$A$50, MATCH(A17, $M$7:$M$50, 0)), "###"), $C$7:$C$50, TRUE) + COUNTIFS($M$7:$M$50, IFERROR(INDEX($A$7:$A$50, MATCH(IFERROR(INDEX($A$7:$A$50, MATCH(A17, $M$7:$M$50, 0)), "###"), $M$7:$M$50, 0)), "###"), $C$7:$C$50, TRUE) + COUNTIFS($M$7:$M$50, IFERROR(INDEX($A$7:$A$50, MATCH(IFERROR(INDEX($A$7:$A$50, MATCH(IFERROR(INDEX($A$7:$A$50, MATCH(A17, $M$7:$M$50, 0)), "###"), $M$7:$M$50, 0)), "###"), $M$7:$M$50, 0)), "###"), $C$7:$C$50, TRUE))>0, "Đã hoàn thành bù", IF(OR(ISNUMBER(SEARCH("dời", K17)), ISNUMBER(SEARCH("hoãn", K17))), "Dời lịch", IF(AND(ISNUMBER(IF(L17<>"", L17, B17)), IF(L17<>"", L17, B17)<TODAY()), "Quá hạn", "Đang thực hiện"))))) -> Hoàn thành
A18: =IF(OR(B18<>"", H18<>""), "T" & TEXT(ROW()-6, "00"), "") -> T12 | B18: 46302 | C18: TRUE | D18: 0.75 | E18: 0.875 | F18: Học tập | H18: Theo thời khóa biểu môn học | I18: Cao | J18: =IFERROR(IF(AND(D18<>"", E18<>""), ROUND(MOD(E18 - D18, 1) * 1440,0), IFERROR(VLOOKUP(H18, 'Dữ liệu'!$X$4:$AA$15, 4, FALSE), "")), "") -> 180 | L18: =IF(B18="", "", B18) -> 46302 | N18: =IF(OR(B18="", H18=""), "", IF(C18=TRUE, IF(OR(M18<>"", ISNUMBER(SEARCH("bù", K18&" "&H18)), ISNUMBER(SEARCH("dời", K18&" "&H18)), AND(ISNUMBER(L18), ISNUMBER(B18), L18<>"", B18>L18)), "Hoàn thành bù", "Hoàn thành"), IF((COUNTIFS($M$7:$M$50, A18, $C$7:$C$50, TRUE) + COUNTIFS($M$7:$M$50, IFERROR(INDEX($A$7:$A$50, MATCH(A18, $M$7:$M$50, 0)), "###"), $C$7:$C$50, TRUE) + COUNTIFS($M$7:$M$50, IFERROR(INDEX($A$7:$A$50, MATCH(IFERROR(INDEX($A$7:$A$50, MATCH(A18, $M$7:$M$50, 0)), "###"), $M$7:$M$50, 0)), "###"), $C$7:$C$50, TRUE) + COUNTIFS($M$7:$M$50, IFERROR(INDEX($A$7:$A$50, MATCH(IFERROR(INDEX($A$7:$A$50, MATCH(IFERROR(INDEX($A$7:$A$50, MATCH(A18, $M$7:$M$50, 0)), "###"), $M$7:$M$50, 0)), "###"), $M$7:$M$50, 0)), "###"), $C$7:$C$50, TRUE))>0, "Đã hoàn thành bù", IF(OR(ISNUMBER(SEARCH("dời", K18)), ISNUMBER(SEARCH("hoãn", K18))), "Dời lịch", IF(AND(ISNUMBER(IF(L18<>"", L18, B18)), IF(L18<>"", L18, B18)<TODAY()), "Quá hạn", "Đang thực hiện"))))) -> Hoàn thành
A19: =IF(OR(B19<>"", H19<>""), "T" & TEXT(ROW()-6, "00"), "") -> T13 | B19: 46302 | C19: FALSE | D19: 0.875 | E19: 0.91666667 | F19: IELTS | G19: Vocabulary | H19: Học từ vựng và làm bài tập chủ đề cửa hàng | I19: Khẩn cấp | J19: =IFERROR(IF(AND(D19<>"", E19<>""), ROUND(MOD(E19 - D19, 1) * 1440,0), IFERROR(VLOOKUP(H19, 'Dữ liệu'!$X$4:$AA$15, 4, FALSE), "")), "") -> 60 | L19: =IF(B19="", "", B19) -> 46302 | M19: T08 | N19: =IF(OR(B19="", H19=""), "", IF(C19=TRUE, IF(OR(M19<>"", ISNUMBER(SEARCH("bù", K19&" "&H19)), ISNUMBER(SEARCH("dời", K19&" "&H19)), AND(ISNUMBER(L19), ISNUMBER(B19), L19<>"", B19>L19)), "Hoàn thành bù", "Hoàn thành"), IF((COUNTIFS($M$7:$M$50, A19, $C$7:$C$50, TRUE) + COUNTIFS($M$7:$M$50, IFERROR(INDEX($A$7:$A$50, MATCH(A19, $M$7:$M$50, 0)), "###"), $C$7:$C$50, TRUE) + COUNTIFS($M$7:$M$50, IFERROR(INDEX($A$7:$A$50, MATCH(IFERROR(INDEX($A$7:$A$50, MATCH(A19, $M$7:$M$50, 0)), "###"), $M$7:$M$50, 0)), "###"), $C$7:$C$50, TRUE) + COUNTIFS($M$7:$M$50, IFERROR(INDEX($A$7:$A$50, MATCH(IFERROR(INDEX($A$7:$A$50, MATCH(IFERROR(INDEX($A$7:$A$50, MATCH(A19, $M$7:$M$50, 0)), "###"), $M$7:$M$50, 0)), "###"), $M$7:$M$50, 0)), "###"), $C$7:$C$50, TRUE))>0, "Đã hoàn thành bù", IF(OR(ISNUMBER(SEARCH("dời", K19)), ISNUMBER(SEARCH("hoãn", K19))), "Dời lịch", IF(AND(ISNUMBER(IF(L19<>"", L19, B19)), IF(L19<>"", L19, B19)<TODAY()), "Quá hạn", "Đang thực hiện"))))) -> Đã hoàn thành bù
A20: =IF(OR(B20<>"", H20<>""), "T" & TEXT(ROW()-6, "00"), "") -> T14 | B20: 46302 | C20: FALSE | D20: 0.91666667 | E20: 0.95833333 | F20: Ôn tập | G20: Vocabulary | H20: Ôn từ vừng chủ đề "Vui chơi giải trí" gồm 2 bộ từ vựng | I20: Cao | J20: =IFERROR(IF(AND(D20<>"", E20<>""), ROUND(MOD(E20 - D20, 1) * 1440,0), IFERROR(VLOOKUP(H20, 'Dữ liệu'!$X$4:$AA$15, 4, FALSE), "")), "") -> 60 | L20: =IF(B20="", "", B20) -> 46302 | N20: =IF(OR(B20="", H20=""), "", IF(C20=TRUE, IF(OR(M20<>"", ISNUMBER(SEARCH("bù", K20&" "&H20)), ISNUMBER(SEARCH("dời", K20&" "&H20)), AND(ISNUMBER(L20), ISNUMBER(B20), L20<>"", B20>L20)), "Hoàn thành bù", "Hoàn thành"), IF((COUNTIFS($M$7:$M$50, A20, $C$7:$C$50, TRUE) + COUNTIFS($M$7:$M$50, IFERROR(INDEX($A$7:$A$50, MATCH(A20, $M$7:$M$50, 0)), "###"), $C$7:$C$50, TRUE) + COUNTIFS($M$7:$M$50, IFERROR(INDEX($A$7:$A$50, MATCH(IFERROR(INDEX($A$7:$A$50, MATCH(A20, $M$7:$M$50, 0)), "###"), $M$7:$M$50, 0)), "###"), $C$7:$C$50, TRUE) + COUNTIFS($M$7:$M$50, IFERROR(INDEX($A$7:$A$50, MATCH(IFERROR(INDEX($A$7:$A$50, MATCH(IFERROR(INDEX($A$7:$A$50, MATCH(A20, $M$7:$M$50, 0)), "###"), $M$7:$M$50, 0)), "###"), $M$7:$M$50, 0)), "###"), $C$7:$C$50, TRUE))>0, "Đã hoàn thành bù", IF(OR(ISNUMBER(SEARCH("dời", K20)), ISNUMBER(SEARCH("hoãn", K20))), "Dời lịch", IF(AND(ISNUMBER(IF(L20<>"", L20, B20)), IF(L20<>"", L20, B20)<TODAY()), "Quá hạn", "Đang thực hiện"))))) -> Đã hoàn thành bù
A21: =IF(OR(B21<>"", H21<>""), "T" & TEXT(ROW()-6, "00"), "") -> T15 | B21: 46303 | C21: TRUE | D21: 0.29166667 | E21: 0.64583333 | F21: Làm thêm | H21: Làm 250 dòng Properties | I21: Cao | J21: =IFERROR(IF(AND(D21<>"", E21<>""), ROUND(MOD(E21 - D21, 1) * 1440,0), IFERROR(VLOOKUP(H21, 'Dữ liệu'!$X$4:$AA$15, 4, FALSE), "")), "") -> 510 | L21: =IF(B21="", "", B21) -> 46303 | N21: =IF(OR(B21="", H21=""), "", IF(C21=TRUE, IF(OR(M21<>"", ISNUMBER(SEARCH("bù", K21&" "&H21)), ISNUMBER(SEARCH("dời", K21&" "&H21)), AND(ISNUMBER(L21), ISNUMBER(B21), L21<>"", B21>L21)), "Hoàn thành bù", "Hoàn thành"), IF((COUNTIFS($M$7:$M$50, A21, $C$7:$C$50, TRUE) + COUNTIFS($M$7:$M$50, IFERROR(INDEX($A$7:$A$50, MATCH(A21, $M$7:$M$50, 0)), "###"), $C$7:$C$50, TRUE) + COUNTIFS($M$7:$M$50, IFERROR(INDEX($A$7:$A$50, MATCH(IFERROR(INDEX($A$7:$A$50, MATCH(A21, $M$7:$M$50, 0)), "###"), $M$7:$M$50, 0)), "###"), $C$7:$C$50, TRUE) + COUNTIFS($M$7:$M$50, IFERROR(INDEX($A$7:$A$50, MATCH(IFERROR(INDEX($A$7:$A$50, MATCH(IFERROR(INDEX($A$7:$A$50, MATCH(A21, $M$7:$M$50, 0)), "###"), $M$7:$M$50, 0)), "###"), $M$7:$M$50, 0)), "###"), $C$7:$C$50, TRUE))>0, "Đã hoàn thành bù", IF(OR(ISNUMBER(SEARCH("dời", K21)), ISNUMBER(SEARCH("hoãn", K21))), "Dời lịch", IF(AND(ISNUMBER(IF(L21<>"", L21, B21)), IF(L21<>"", L21, B21)<TODAY()), "Quá hạn", "Đang thực hiện"))))) -> Hoàn thành
A22: =IF(OR(B22<>"", H22<>""), "T" & TEXT(ROW()-6, "00"), "") -> T16 | B22: 46303 | C22: TRUE | D22: 0.66666667 | E22: 0.75 | F22: Học tập | H22: Đi học thêm Ielts | I22: Cao | J22: =IFERROR(IF(AND(D22<>"", E22<>""), ROUND(MOD(E22 - D22, 1) * 1440,0), IFERROR(VLOOKUP(H22, 'Dữ liệu'!$X$4:$AA$15, 4, FALSE), "")), "") -> 120 | L22: =IF(B22="", "", B22) -> 46303 | N22: =IF(OR(B22="", H22=""), "", IF(C22=TRUE, IF(OR(M22<>"", ISNUMBER(SEARCH("bù", K22&" "&H22)), ISNUMBER(SEARCH("dời", K22&" "&H22)), AND(ISNUMBER(L22), ISNUMBER(B22), L22<>"", B22>L22)), "Hoàn thành bù", "Hoàn thành"), IF((COUNTIFS($M$7:$M$50, A22, $C$7:$C$50, TRUE) + COUNTIFS($M$7:$M$50, IFERROR(INDEX($A$7:$A$50, MATCH(A22, $M$7:$M$50, 0)), "###"), $C$7:$C$50, TRUE) + COUNTIFS($M$7:$M$50, IFERROR(INDEX($A$7:$A$50, MATCH(IFERROR(INDEX($A$7:$A$50, MATCH(A22, $M$7:$M$50, 0)), "###"), $M$7:$M$50, 0)), "###"), $C$7:$C$50, TRUE) + COUNTIFS($M$7:$M$50, IFERROR(INDEX($A$7:$A$50, MATCH(IFERROR(INDEX($A$7:$A$50, MATCH(IFERROR(INDEX($A$7:$A$50, MATCH(A22, $M$7:$M$50, 0)), "###"), $M$7:$M$50, 0)), "###"), $M$7:$M$50, 0)), "###"), $C$7:$C$50, TRUE))>0, "Đã hoàn thành bù", IF(OR(ISNUMBER(SEARCH("dời", K22)), ISNUMBER(SEARCH("hoãn", K22))), "Dời lịch", IF(AND(ISNUMBER(IF(L22<>"", L22, B22)), IF(L22<>"", L22, B22)<TODAY()), "Quá hạn", "Đang thực hiện"))))) -> Hoàn thành
A23: =IF(OR(B23<>"", H23<>""), "T" & TEXT(ROW()-6, "00"), "") -> T17 | B23: 46303 | C23: TRUE | D23: 0.75 | E23: 0.875 | F23: Học tập | H23: Theo thời khóa biểu môn học | I23: Cao | J23: =IFERROR(IF(AND(D23<>"", E23<>""), ROUND(MOD(E23 - D23, 1) * 1440,0), IFERROR(VLOOKUP(H23, 'Dữ liệu'!$X$4:$AA$15, 4, FALSE), "")), "") -> 180 | L23: =IF(B23="", "", B23) -> 46303 | N23: =IF(OR(B23="", H23=""), "", IF(C23=TRUE, IF(OR(M23<>"", ISNUMBER(SEARCH("bù", K23&" "&H23)), ISNUMBER(SEARCH("dời", K23&" "&H23)), AND(ISNUMBER(L23), ISNUMBER(B23), L23<>"", B23>L23)), "Hoàn thành bù", "Hoàn thành"), IF((COUNTIFS($M$7:$M$50, A23, $C$7:$C$50, TRUE) + COUNTIFS($M$7:$M$50, IFERROR(INDEX($A$7:$A$50, MATCH(A23, $M$7:$M$50, 0)), "###"), $C$7:$C$50, TRUE) + COUNTIFS($M$7:$M$50, IFERROR(INDEX($A$7:$A$50, MATCH(IFERROR(INDEX($A$7:$A$50, MATCH(A23, $M$7:$M$50, 0)), "###"), $M$7:$M$50, 0)), "###"), $C$7:$C$50, TRUE) + COUNTIFS($M$7:$M$50, IFERROR(INDEX($A$7:$A$50, MATCH(IFERROR(INDEX($A$7:$A$50, MATCH(IFERROR(INDEX($A$7:$A$50, MATCH(A23, $M$7:$M$50, 0)), "###"), $M$7:$M$50, 0)), "###"), $M$7:$M$50, 0)), "###"), $C$7:$C$50, TRUE))>0, "Đã hoàn thành bù", IF(OR(ISNUMBER(SEARCH("dời", K23)), ISNUMBER(SEARCH("hoãn", K23))), "Dời lịch", IF(AND(ISNUMBER(IF(L23<>"", L23, B23)), IF(L23<>"", L23, B23)<TODAY()), "Quá hạn", "Đang thực hiện"))))) -> Hoàn thành
A24: =IF(OR(B24<>"", H24<>""), "T" & TEXT(ROW()-6, "00"), "") -> T18 | B24: 46303 | C24: FALSE | D24: 0.875 | E24: 0.91666667 | F24: IELTS | G24: Vocabulary | H24: Học từ vựng và làm bài tập chủ đề cửa hàng | I24: Khẩn cấp | J24: =IFERROR(IF(AND(D24<>"", E24<>""), ROUND(MOD(E24 - D24, 1) * 1440,0), IFERROR(VLOOKUP(H24, 'Dữ liệu'!$X$4:$AA$15, 4, FALSE), "")), "") -> 60 | L24: =IF(B24="", "", B24) -> 46303 | M24: T13 | N24: =IF(OR(B24="", H24=""), "", IF(C24=TRUE, IF(OR(M24<>"", ISNUMBER(SEARCH("bù", K24&" "&H24)), ISNUMBER(SEARCH("dời", K24&" "&H24)), AND(ISNUMBER(L24), ISNUMBER(B24), L24<>"", B24>L24)), "Hoàn thành bù", "Hoàn thành"), IF((COUNTIFS($M$7:$M$50, A24, $C$7:$C$50, TRUE) + COUNTIFS($M$7:$M$50, IFERROR(INDEX($A$7:$A$50, MATCH(A24, $M$7:$M$50, 0)), "###"), $C$7:$C$50, TRUE) + COUNTIFS($M$7:$M$50, IFERROR(INDEX($A$7:$A$50, MATCH(IFERROR(INDEX($A$7:$A$50, MATCH(A24, $M$7:$M$50, 0)), "###"), $M$7:$M$50, 0)), "###"), $C$7:$C$50, TRUE) + COUNTIFS($M$7:$M$50, IFERROR(INDEX($A$7:$A$50, MATCH(IFERROR(INDEX($A$7:$A$50, MATCH(IFERROR(INDEX($A$7:$A$50, MATCH(A24, $M$7:$M$50, 0)), "###"), $M$7:$M$50, 0)), "###"), $M$7:$M$50, 0)), "###"), $C$7:$C$50, TRUE))>0, "Đã hoàn thành bù", IF(OR(ISNUMBER(SEARCH("dời", K24)), ISNUMBER(SEARCH("hoãn", K24))), "Dời lịch", IF(AND(ISNUMBER(IF(L24<>"", L24, B24)), IF(L24<>"", L24, B24)<TODAY()), "Quá hạn", "Đang thực hiện"))))) -> Đã hoàn thành bù
A25: =IF(OR(B25<>"", H25<>""), "T" & TEXT(ROW()-6, "00"), "") -> T19 | B25: 46303 | C25: FALSE | D25: 0.91666667 | E25: 0.95833333 | F25: Ôn tập | G25: Vocabulary | H25: Ôn từ vừng chủ đề "Cảm xúc và quan điểm" gồm 2 bộ từ vựng | I25: Cao | J25: =IFERROR(IF(AND(D25<>"", E25<>""), ROUND(MOD(E25 - D25, 1) * 1440,0), IFERROR(VLOOKUP(H25, 'Dữ liệu'!$X$4:$AA$15, 4, FALSE), "")), "") -> 60 | L25: =IF(B25="", "", B25) -> 46303 | N25: =IF(OR(B25="", H25=""), "", IF(C25=TRUE, IF(OR(M25<>"", ISNUMBER(SEARCH("bù", K25&" "&H25)), ISNUMBER(SEARCH("dời", K25&" "&H25)), AND(ISNUMBER(L25), ISNUMBER(B25), L25<>"", B25>L25)), "Hoàn thành bù", "Hoàn thành"), IF((COUNTIFS($M$7:$M$50, A25, $C$7:$C$50, TRUE) + COUNTIFS($M$7:$M$50, IFERROR(INDEX($A$7:$A$50, MATCH(A25, $M$7:$M$50, 0)), "###"), $C$7:$C$50, TRUE) + COUNTIFS($M$7:$M$50, IFERROR(INDEX($A$7:$A$50, MATCH(IFERROR(INDEX($A$7:$A$50, MATCH(A25, $M$7:$M$50, 0)), "###"), $M$7:$M$50, 0)), "###"), $C$7:$C$50, TRUE) + COUNTIFS($M$7:$M$50, IFERROR(INDEX($A$7:$A$50, MATCH(IFERROR(INDEX($A$7:$A$50, MATCH(IFERROR(INDEX($A$7:$A$50, MATCH(A25, $M$7:$M$50, 0)), "###"), $M$7:$M$50, 0)), "###"), $M$7:$M$50, 0)), "###"), $C$7:$C$50, TRUE))>0, "Đã hoàn thành bù", IF(OR(ISNUMBER(SEARCH("dời", K25)), ISNUMBER(SEARCH("hoãn", K25))), "Dời lịch", IF(AND(ISNUMBER(IF(L25<>"", L25, B25)), IF(L25<>"", L25, B25)<TODAY()), "Quá hạn", "Đang thực hiện"))))) -> Quá hạn
A26: =IF(OR(B26<>"", H26<>""), "T" & TEXT(ROW()-6, "00"), "") -> T20 | B26: 46303 | C26: FALSE | D26: 0.95833333 | E26: 0.99652778 | F26: Ôn tập | G26: Vocabulary | H26: Ôn từ vừng chủ đề "Vui chơi giải trí" gồm 2 bộ từ vựng | I26: Cao | J26: =IFERROR(IF(AND(D26<>"", E26<>""), ROUND(MOD(E26 - D26, 1) * 1440,0), IFERROR(VLOOKUP(H26, 'Dữ liệu'!$X$4:$AA$15, 4, FALSE), "")), "") -> 55 | L26: =IF(B26="", "", B26) -> 46303 | M26: T14 | N26: =IF(OR(B26="", H26=""), "", IF(C26=TRUE, IF(OR(M26<>"", ISNUMBER(SEARCH("bù", K26&" "&H26)), ISNUMBER(SEARCH("dời", K26&" "&H26)), AND(ISNUMBER(L26), ISNUMBER(B26), L26<>"", B26>L26)), "Hoàn thành bù", "Hoàn thành"), IF((COUNTIFS($M$7:$M$50, A26, $C$7:$C$50, TRUE) + COUNTIFS($M$7:$M$50, IFERROR(INDEX($A$7:$A$50, MATCH(A26, $M$7:$M$50, 0)), "###"), $C$7:$C$50, TRUE) + COUNTIFS($M$7:$M$50, IFERROR(INDEX($A$7:$A$50, MATCH(IFERROR(INDEX($A$7:$A$50, MATCH(A26, $M$7:$M$50, 0)), "###"), $M$7:$M$50, 0)), "###"), $C$7:$C$50, TRUE) + COUNTIFS($M$7:$M$50, IFERROR(INDEX($A$7:$A$50, MATCH(IFERROR(INDEX($A$7:$A$50, MATCH(IFERROR(INDEX($A$7:$A$50, MATCH(A26, $M$7:$M$50, 0)), "###"), $M$7:$M$50, 0)), "###"), $M$7:$M$50, 0)), "###"), $C$7:$C$50, TRUE))>0, "Đã hoàn thành bù", IF(OR(ISNUMBER(SEARCH("dời", K26)), ISNUMBER(SEARCH("hoãn", K26))), "Dời lịch", IF(AND(ISNUMBER(IF(L26<>"", L26, B26)), IF(L26<>"", L26, B26)<TODAY()), "Quá hạn", "Đang thực hiện"))))) -> Đã hoàn thành bù
A27: =IF(OR(B27<>"", H27<>""), "T" & TEXT(ROW()-6, "00"), "") -> T21 | B27: 46304 | C27: TRUE | D27: 0.29166667 | E27: 0.64583333 | F27: Làm thêm | H27: Làm 250 dòng Properties | I27: Cao | J27: =IFERROR(IF(AND(D27<>"", E27<>""), ROUND(MOD(E27 - D27, 1) * 1440,0), IFERROR(VLOOKUP(H27, 'Dữ liệu'!$X$4:$AA$15, 4, FALSE), "")), "") -> 510 | L27: =IF(B27="", "", B27) -> 46304 | N27: =IF(OR(B27="", H27=""), "", IF(C27=TRUE, IF(OR(M27<>"", ISNUMBER(SEARCH("bù", K27&" "&H27)), ISNUMBER(SEARCH("dời", K27&" "&H27)), AND(ISNUMBER(L27), ISNUMBER(B27), L27<>"", B27>L27)), "Hoàn thành bù", "Hoàn thành"), IF((COUNTIFS($M$7:$M$50, A27, $C$7:$C$50, TRUE) + COUNTIFS($M$7:$M$50, IFERROR(INDEX($A$7:$A$50, MATCH(A27, $M$7:$M$50, 0)), "###"), $C$7:$C$50, TRUE) + COUNTIFS($M$7:$M$50, IFERROR(INDEX($A$7:$A$50, MATCH(IFERROR(INDEX($A$7:$A$50, MATCH(A27, $M$7:$M$50, 0)), "###"), $M$7:$M$50, 0)), "###"), $C$7:$C$50, TRUE) + COUNTIFS($M$7:$M$50, IFERROR(INDEX($A$7:$A$50, MATCH(IFERROR(INDEX($A$7:$A$50, MATCH(IFERROR(INDEX($A$7:$A$50, MATCH(A27, $M$7:$M$50, 0)), "###"), $M$7:$M$50, 0)), "###"), $M$7:$M$50, 0)), "###"), $C$7:$C$50, TRUE))>0, "Đã hoàn thành bù", IF(OR(ISNUMBER(SEARCH("dời", K27)), ISNUMBER(SEARCH("hoãn", K27))), "Dời lịch", IF(AND(ISNUMBER(IF(L27<>"", L27, B27)), IF(L27<>"", L27, B27)<TODAY()), "Quá hạn", "Đang thực hiện"))))) -> Hoàn thành
A28: =IF(OR(B28<>"", H28<>""), "T" & TEXT(ROW()-6, "00"), "") -> T22 | B28: 46304 | C28: TRUE | D28: 0.66666667 | E28: 0.75 | F28: Học tập | H28: Đi học thêm Ielts | I28: Cao | J28: =IFERROR(IF(AND(D28<>"", E28<>""), ROUND(MOD(E28 - D28, 1) * 1440,0), IFERROR(VLOOKUP(H28, 'Dữ liệu'!$X$4:$AA$15, 4, FALSE), "")), "") -> 120 | L28: =IF(B28="", "", B28) -> 46304 | N28: =IF(OR(B28="", H28=""), "", IF(C28=TRUE, IF(OR(M28<>"", ISNUMBER(SEARCH("bù", K28&" "&H28)), ISNUMBER(SEARCH("dời", K28&" "&H28)), AND(ISNUMBER(L28), ISNUMBER(B28), L28<>"", B28>L28)), "Hoàn thành bù", "Hoàn thành"), IF((COUNTIFS($M$7:$M$50, A28, $C$7:$C$50, TRUE) + COUNTIFS($M$7:$M$50, IFERROR(INDEX($A$7:$A$50, MATCH(A28, $M$7:$M$50, 0)), "###"), $C$7:$C$50, TRUE) + COUNTIFS($M$7:$M$50, IFERROR(INDEX($A$7:$A$50, MATCH(IFERROR(INDEX($A$7:$A$50, MATCH(A28, $M$7:$M$50, 0)), "###"), $M$7:$M$50, 0)), "###"), $C$7:$C$50, TRUE) + COUNTIFS($M$7:$M$50, IFERROR(INDEX($A$7:$A$50, MATCH(IFERROR(INDEX($A$7:$A$50, MATCH(IFERROR(INDEX($A$7:$A$50, MATCH(A28, $M$7:$M$50, 0)), "###"), $M$7:$M$50, 0)), "###"), $M$7:$M$50, 0)), "###"), $C$7:$C$50, TRUE))>0, "Đã hoàn thành bù", IF(OR(ISNUMBER(SEARCH("dời", K28)), ISNUMBER(SEARCH("hoãn", K28))), "Dời lịch", IF(AND(ISNUMBER(IF(L28<>"", L28, B28)), IF(L28<>"", L28, B28)<TODAY()), "Quá hạn", "Đang thực hiện"))))) -> Hoàn thành
A29: =IF(OR(B29<>"", H29<>""), "T" & TEXT(ROW()-6, "00"), "") -> T23 | B29: 46304 | C29: TRUE | D29: 0.75 | E29: 0.875 | F29: Học tập | H29: Theo thời khóa biểu môn học | I29: Cao | J29: =IFERROR(IF(AND(D29<>"", E29<>""), ROUND(MOD(E29 - D29, 1) * 1440,0), IFERROR(VLOOKUP(H29, 'Dữ liệu'!$X$4:$AA$15, 4, FALSE), "")), "") -> 180 | L29: =IF(B29="", "", B29) -> 46304 | N29: =IF(OR(B29="", H29=""), "", IF(C29=TRUE, IF(OR(M29<>"", ISNUMBER(SEARCH("bù", K29&" "&H29)), ISNUMBER(SEARCH("dời", K29&" "&H29)), AND(ISNUMBER(L29), ISNUMBER(B29), L29<>"", B29>L29)), "Hoàn thành bù", "Hoàn thành"), IF((COUNTIFS($M$7:$M$50, A29, $C$7:$C$50, TRUE) + COUNTIFS($M$7:$M$50, IFERROR(INDEX($A$7:$A$50, MATCH(A29, $M$7:$M$50, 0)), "###"), $C$7:$C$50, TRUE) + COUNTIFS($M$7:$M$50, IFERROR(INDEX($A$7:$A$50, MATCH(IFERROR(INDEX($A$7:$A$50, MATCH(A29, $M$7:$M$50, 0)), "###"), $M$7:$M$50, 0)), "###"), $C$7:$C$50, TRUE) + COUNTIFS($M$7:$M$50, IFERROR(INDEX($A$7:$A$50, MATCH(IFERROR(INDEX($A$7:$A$50, MATCH(IFERROR(INDEX($A$7:$A$50, MATCH(A29, $M$7:$M$50, 0)), "###"), $M$7:$M$50, 0)), "###"), $M$7:$M$50, 0)), "###"), $C$7:$C$50, TRUE))>0, "Đã hoàn thành bù", IF(OR(ISNUMBER(SEARCH("dời", K29)), ISNUMBER(SEARCH("hoãn", K29))), "Dời lịch", IF(AND(ISNUMBER(IF(L29<>"", L29, B29)), IF(L29<>"", L29, B29)<TODAY()), "Quá hạn", "Đang thực hiện"))))) -> Hoàn thành
A30: =IF(OR(B30<>"", H30<>""), "T" & TEXT(ROW()-6, "00"), "") -> T24 | B30: 46304 | C30: TRUE | D30: 0.875 | E30: 0.91666667 | F30: IELTS | G30: Vocabulary | H30: Học từ vựng và làm bài tập chủ đề cửa hàng | I30: Khẩn cấp | J30: =IFERROR(IF(AND(D30<>"", E30<>""), ROUND(MOD(E30 - D30, 1) * 1440,0), IFERROR(VLOOKUP(H30, 'Dữ liệu'!$X$4:$AA$15, 4, FALSE), "")), "") -> 60 | L30: =IF(B30="", "", B30) -> 46304 | M30: T18 | N30: =IF(OR(B30="", H30=""), "", IF(C30=TRUE, IF(OR(M30<>"", ISNUMBER(SEARCH("bù", K30&" "&H30)), ISNUMBER(SEARCH("dời", K30&" "&H30)), AND(ISNUMBER(L30), ISNUMBER(B30), L30<>"", B30>L30)), "Hoàn thành bù", "Hoàn thành"), IF((COUNTIFS($M$7:$M$50, A30, $C$7:$C$50, TRUE) + COUNTIFS($M$7:$M$50, IFERROR(INDEX($A$7:$A$50, MATCH(A30, $M$7:$M$50, 0)), "###"), $C$7:$C$50, TRUE) + COUNTIFS($M$7:$M$50, IFERROR(INDEX($A$7:$A$50, MATCH(IFERROR(INDEX($A$7:$A$50, MATCH(A30, $M$7:$M$50, 0)), "###"), $M$7:$M$50, 0)), "###"), $C$7:$C$50, TRUE) + COUNTIFS($M$7:$M$50, IFERROR(INDEX($A$7:$A$50, MATCH(IFERROR(INDEX($A$7:$A$50, MATCH(IFERROR(INDEX($A$7:$A$50, MATCH(A30, $M$7:$M$50, 0)), "###"), $M$7:$M$50, 0)), "###"), $M$7:$M$50, 0)), "###"), $C$7:$C$50, TRUE))>0, "Đã hoàn thành bù", IF(OR(ISNUMBER(SEARCH("dời", K30)), ISNUMBER(SEARCH("hoãn", K30))), "Dời lịch", IF(AND(ISNUMBER(IF(L30<>"", L30, B30)), IF(L30<>"", L30, B30)<TODAY()), "Quá hạn", "Đang thực hiện"))))) -> Hoàn thành bù
A31: =IF(OR(B31<>"", H31<>""), "T" & TEXT(ROW()-6, "00"), "") -> T25 | B31: 46304 | C31: FALSE | D31: 0.91666667 | E31: 0.95833333 | F31: Ôn tập | G31: Vocabulary | H31: Ôn từ vừng chủ đề "Cảm xúc và quan điểm" gồm 2 bộ từ vựng | I31: Khẩn cấp | J31: =IFERROR(IF(AND(D31<>"", E31<>""), ROUND(MOD(E31 - D31, 1) * 1440,0), IFERROR(VLOOKUP(H31, 'Dữ liệu'!$X$4:$AA$15, 4, FALSE), "")), "") -> 60 | L31: =IF(B31="", "", B31) -> 46304 | M31: T19 | N31: =IF(OR(B31="", H31=""), "", IF(C31=TRUE, IF(OR(M31<>"", ISNUMBER(SEARCH("bù", K31&" "&H31)), ISNUMBER(SEARCH("dời", K31&" "&H31)), AND(ISNUMBER(L31), ISNUMBER(B31), L31<>"", B31>L31)), "Hoàn thành bù", "Hoàn thành"), IF((COUNTIFS($M$7:$M$50, A31, $C$7:$C$50, TRUE) + COUNTIFS($M$7:$M$50, IFERROR(INDEX($A$7:$A$50, MATCH(A31, $M$7:$M$50, 0)), "###"), $C$7:$C$50, TRUE) + COUNTIFS($M$7:$M$50, IFERROR(INDEX($A$7:$A$50, MATCH(IFERROR(INDEX($A$7:$A$50, MATCH(A31, $M$7:$M$50, 0)), "###"), $M$7:$M$50, 0)), "###"), $C$7:$C$50, TRUE) + COUNTIFS($M$7:$M$50, IFERROR(INDEX($A$7:$A$50, MATCH(IFERROR(INDEX($A$7:$A$50, MATCH(IFERROR(INDEX($A$7:$A$50, MATCH(A31, $M$7:$M$50, 0)), "###"), $M$7:$M$50, 0)), "###"), $M$7:$M$50, 0)), "###"), $C$7:$C$50, TRUE))>0, "Đã hoàn thành bù", IF(OR(ISNUMBER(SEARCH("dời", K31)), ISNUMBER(SEARCH("hoãn", K31))), "Dời lịch", IF(AND(ISNUMBER(IF(L31<>"", L31, B31)), IF(L31<>"", L31, B31)<TODAY()), "Quá hạn", "Đang thực hiện"))))) -> Quá hạn
A32: =IF(OR(B32<>"", H32<>""), "T" & TEXT(ROW()-6, "00"), "") -> T26 | B32: 46304 | C32: FALSE | D32: 0.95833333 | E32: 0.99652778 | F32: Ôn tập | G32: Vocabulary | H32: Ôn từ vừng chủ đề "Vui chơi giải trí" gồm 2 bộ từ vựng | I32: Khẩn cấp | J32: =IFERROR(IF(AND(D32<>"", E32<>""), ROUND(MOD(E32 - D32, 1) * 1440,0), IFERROR(VLOOKUP(H32, 'Dữ liệu'!$X$4:$AA$15, 4, FALSE), "")), "") -> 55 | L32: =IF(B32="", "", B32) -> 46304 | M32: T20 | N32: =IF(OR(B32="", H32=""), "", IF(C32=TRUE, IF(OR(M32<>"", ISNUMBER(SEARCH("bù", K32&" "&H32)), ISNUMBER(SEARCH("dời", K32&" "&H32)), AND(ISNUMBER(L32), ISNUMBER(B32), L32<>"", B32>L32)), "Hoàn thành bù", "Hoàn thành"), IF((COUNTIFS($M$7:$M$50, A32, $C$7:$C$50, TRUE) + COUNTIFS($M$7:$M$50, IFERROR(INDEX($A$7:$A$50, MATCH(A32, $M$7:$M$50, 0)), "###"), $C$7:$C$50, TRUE) + COUNTIFS($M$7:$M$50, IFERROR(INDEX($A$7:$A$50, MATCH(IFERROR(INDEX($A$7:$A$50, MATCH(A32, $M$7:$M$50, 0)), "###"), $M$7:$M$50, 0)), "###"), $C$7:$C$50, TRUE) + COUNTIFS($M$7:$M$50, IFERROR(INDEX($A$7:$A$50, MATCH(IFERROR(INDEX($A$7:$A$50, MATCH(IFERROR(INDEX($A$7:$A$50, MATCH(A32, $M$7:$M$50, 0)), "###"), $M$7:$M$50, 0)), "###"), $M$7:$M$50, 0)), "###"), $C$7:$C$50, TRUE))>0, "Đã hoàn thành bù", IF(OR(ISNUMBER(SEARCH("dời", K32)), ISNUMBER(SEARCH("hoãn", K32))), "Dời lịch", IF(AND(ISNUMBER(IF(L32<>"", L32, B32)), IF(L32<>"", L32, B32)<TODAY()), "Quá hạn", "Đang thực hiện"))))) -> Đã hoàn thành bù
A33: =IF(OR(B33<>"", H33<>""), "T" & TEXT(ROW()-6, "00"), "") -> T27 | B33: 46305 | C33: TRUE | D33: 0.29166667 | E33: 0.64583333 | F33: Làm thêm | H33: Làm 250 dòng Properties | I33: Cao | J33: =IFERROR(IF(AND(D33<>"", E33<>""), ROUND(MOD(E33 - D33, 1) * 1440,0), IFERROR(VLOOKUP(H33, 'Dữ liệu'!$X$4:$AA$15, 4, FALSE), "")), "") -> 510 | L33: =IF(B33="", "", B33) -> 46305 | N33: =IF(OR(B33="", H33=""), "", IF(C33=TRUE, IF(OR(M33<>"", ISNUMBER(SEARCH("bù", K33&" "&H33)), ISNUMBER(SEARCH("dời", K33&" "&H33)), AND(ISNUMBER(L33), ISNUMBER(B33), L33<>"", B33>L33)), "Hoàn thành bù", "Hoàn thành"), IF((COUNTIFS($M$7:$M$50, A33, $C$7:$C$50, TRUE) + COUNTIFS($M$7:$M$50, IFERROR(INDEX($A$7:$A$50, MATCH(A33, $M$7:$M$50, 0)), "###"), $C$7:$C$50, TRUE) + COUNTIFS($M$7:$M$50, IFERROR(INDEX($A$7:$A$50, MATCH(IFERROR(INDEX($A$7:$A$50, MATCH(A33, $M$7:$M$50, 0)), "###"), $M$7:$M$50, 0)), "###"), $C$7:$C$50, TRUE) + COUNTIFS($M$7:$M$50, IFERROR(INDEX($A$7:$A$50, MATCH(IFERROR(INDEX($A$7:$A$50, MATCH(IFERROR(INDEX($A$7:$A$50, MATCH(A33, $M$7:$M$50, 0)), "###"), $M$7:$M$50, 0)), "###"), $M$7:$M$50, 0)), "###"), $C$7:$C$50, TRUE))>0, "Đã hoàn thành bù", IF(OR(ISNUMBER(SEARCH("dời", K33)), ISNUMBER(SEARCH("hoãn", K33))), "Dời lịch", IF(AND(ISNUMBER(IF(L33<>"", L33, B33)), IF(L33<>"", L33, B33)<TODAY()), "Quá hạn", "Đang thực hiện"))))) -> Hoàn thành
A34: =IF(OR(B34<>"", H34<>""), "T" & TEXT(ROW()-6, "00"), "") -> T28 | B34: 46305 | C34: TRUE | D34: 0.66666667 | E34: 0.75 | F34: Học tập | H34: Đi học thêm Ielts | I34: Cao | J34: =IFERROR(IF(AND(D34<>"", E34<>""), ROUND(MOD(E34 - D34, 1) * 1440,0), IFERROR(VLOOKUP(H34, 'Dữ liệu'!$X$4:$AA$15, 4, FALSE), "")), "") -> 120 | L34: =IF(B34="", "", B34) -> 46305 | N34: =IF(OR(B34="", H34=""), "", IF(C34=TRUE, IF(OR(M34<>"", ISNUMBER(SEARCH("bù", K34&" "&H34)), ISNUMBER(SEARCH("dời", K34&" "&H34)), AND(ISNUMBER(L34), ISNUMBER(B34), L34<>"", B34>L34)), "Hoàn thành bù", "Hoàn thành"), IF((COUNTIFS($M$7:$M$50, A34, $C$7:$C$50, TRUE) + COUNTIFS($M$7:$M$50, IFERROR(INDEX($A$7:$A$50, MATCH(A34, $M$7:$M$50, 0)), "###"), $C$7:$C$50, TRUE) + COUNTIFS($M$7:$M$50, IFERROR(INDEX($A$7:$A$50, MATCH(IFERROR(INDEX($A$7:$A$50, MATCH(A34, $M$7:$M$50, 0)), "###"), $M$7:$M$50, 0)), "###"), $C$7:$C$50, TRUE) + COUNTIFS($M$7:$M$50, IFERROR(INDEX($A$7:$A$50, MATCH(IFERROR(INDEX($A$7:$A$50, MATCH(IFERROR(INDEX($A$7:$A$50, MATCH(A34, $M$7:$M$50, 0)), "###"), $M$7:$M$50, 0)), "###"), $M$7:$M$50, 0)), "###"), $C$7:$C$50, TRUE))>0, "Đã hoàn thành bù", IF(OR(ISNUMBER(SEARCH("dời", K34)), ISNUMBER(SEARCH("hoãn", K34))), "Dời lịch", IF(AND(ISNUMBER(IF(L34<>"", L34, B34)), IF(L34<>"", L34, B34)<TODAY()), "Quá hạn", "Đang thực hiện"))))) -> Hoàn thành
